Workbook

Sheet 🎛️ PANEL DE CONTROL
A1: SIMULADOR DE SCORING PLATAM V2.0 + HÍBRIDO
A2: Ajusta los parámetros abajo y los scores se recalcularán automáticamente
A4: 📊 PESOS DE COMPONENTES PLATAM V2.0
A5: Parámetro | B5: Valor Actual | C5: Máximo | D5: % del Total
A6: Payment Performance (pts) | B6: 600 | C6: 1000 | D6: =B6/1000
A7: Payment Plan History (pts) | B7: 150 | C7: 1000 | D7: =B7/1000
A8: Deterioration Velocity (pts) | B8: 250 | C8: 1000 | D8: =B8/1000
A9: TOTAL (debe sumar 1000) | B9: =B6+B7+B8 | D9: =B9/1000
A11: ⚡ PENALIZACIONES Y BONIFICACIONES
A12: Concepto | B12: Valor | C12: Unidad | D12: Descripción
A13: Penalización DPD >30 días | B13: 50 | C13: puntos | D13: Resta del score total
A14: Bonificación >90% pagos a tiempo | B14: 30 | C14: puntos | D14: Suma al score total
A15: Penalización utilización >80% | B15: 20 | C15: puntos | D15: Resta del score total
A16: Bonificación cliente >24 meses | B16: 25 | C16: puntos | D16: Suma al score total
A18: 🔄 PESOS DEL SISTEMA HÍBRIDO
A19: Categoría Cliente | B19: Peso PLATAM | C19: Peso HCPN | D19: Total
A20: Muy Nuevo (< 3 meses) | B20: 0.3 | C20: =1-B20 | D20: =B20+C20
A21: Nuevo (3-6 meses) | B21: 0.4 | C21: =1-B21 | D21: =B21+C21
A22: Intermedio (6-12 meses) | B22: 0.5 | C22: =1-B22 | D22: =B22+C22
A23: Establecido (12-24 meses) | B23: 0.6 | C23: =1-B23 | D23: =B23+C23
A24: Maduro (> 24 meses) | B24: 0.7 | C24: =1-B24 | D24: =B24+C24
A26: 📏 UMBRALES DE CATEGORIZACIÓN
A27: Rating | B27: Score Mínimo | C27: Score Máximo | D27: Descripción
A28: A+ | B28: 900 | C28: 1000 | D28: Excelente
A29: A | B29: 850 | C29: 899 | D29: Muy Bueno
A30: A- | B30: 800 | C30: 849 | D30: Bueno Superior
A31: B+ | B31: 750 | C31: 799 | D31: Bueno
A32: B | B32: 700 | C32: 749 | D32: Aceptable Superior
A33: B- | B33: 650 | C33: 699 | D33: Aceptable
A34: C+ | B34: 600 | C34: 649 | D34: Regular Superior
A35: C | B35: 550 | C35: 599 | D35: Regular
A36: C- | B36: 500 | C36: 549 | D36: Regular Bajo
A37: D | B37: 400 | C37: 499 | D37: Deficiente
A38: F | B38: 0 | C38: 399 | D38: Muy Deficiente
A40: 💡 INSTRUCCIONES:
A41: 1. Cambia los valores en las celdas AZULES
A42: 2. Los pesos de componentes deben sumar 1000 puntos
A43: 3. Los scores se recalcularán automáticamente en la hoja 'Scores Simulados'
A44: 4. Compara los resultados en la hoja 'Comparación'
A45: 5. Usa la hoja 'Análisis' para ver distribuciones

Sheet 📊 Datos Originales
A1: cedula | B1: client_name | C1: score_payment_performance | D1: score_payment_plan | E1: score_deterioration | F1: platam_score | G1: platam_rating | H1: experian_score_normalized | I1: hybrid_score | J1: hybrid_rating | K1: payment_id_count | L1: days_past_due_mean | M1: pct_late | N1: pct_utilization | O1: months_as_client | P1: categoria_madurez | Q1: peso_platam_usado
A2: 1006157869 | C2: 300 | D2: 150 | E2: 125 | F2: 575 | G2: C | H2: 715.36797 | I2: 687.3 | J2: B- | N2: 23.3084 | O2: 0 | P2: muy_nuevo | Q2: 0.2
A3: 74858339 | C3: 300 | D3: 150 | E3: 125 | F3: 575 | G3: C | H3: 884.19913 | I3: 822.4 | J3: A- | N3: 69.824 | O3: 0 | P3: muy_nuevo | Q3: 0.2
A4: 1010240702 | C4: 300 | D4: 150 | E4: 125 | F4: 575 | G4: C | H4: 750 | I4: 715 | J4: B | N4: 0 | O4: 0 | P4: muy_nuevo | Q4: 0.2
A5: 1126427264 | C5: 300 | D5: 150 | E5: 125 | F5: 575 | G5: C | H5: 822.51082 | I5: 773 | J5: B+ | N5: 37.524967 | O5: 0 | P5: muy_nuevo | Q5: 0.2
A6: 1002499770 | C6: 300 | D6: 100 | E6: 125 | F6: 525 | G6: C- | H6: 719.69697 | I6: 680.8 | J6: B- | N6: 0 | O6: 0 | P6: muy_nuevo | Q6: 0.2
A7: 1121820971 | C7: 300 | D7: 150 | E7: 125 | F7: 575 | G7: C | H7: 866.88312 | I7: 808.5 | J7: A- | N7: 0 | O7: 0 | P7: muy_nuevo | Q7: 0.2
A8: 1006218030 | C8: 300 | D8: 150 | E8: 125 | F8: 575 | G8: C | H8: 775.97403 | I8: 735.8 | J8: B | N8: 69.522867 | O8: 0 | P8: muy_nuevo | Q8: 0.2
A9: 1114458785 | C9: 300 | D9: 100 | E9: 125 | F9: 525 | G9: C- | H9: 788.96104 | I9: 736.2 | J9: B | N9: 0 | O9: 0 | P9: muy_nuevo | Q9: 0.2
A10: 31842592 | C10: 300 | D10: 150 | E10: 125 | F10: 575 | G10: C | H10: 860.38961 | I10: 803.3 | J10: A- | N10: 76.03295 | O10: 0 | P10: muy_nuevo | Q10: 0.2
A11: 901973300 | C11: 300 | D11: 150 | E11: 125 | F11: 575 | G11: C | I11: 575 | J11: C | N11: 0 | O11: 0 | P11: muy_nuevo | Q11: 1
A12: 66661722 | C12: 300 | D12: 150 | E12: 125 | F12: 575 | G12: C | H12: 861.47186 | I12: 804.2 | J12: A- | N12: 29.078633 | O12: 0 | P12: muy_nuevo | Q12: 0.2
A13: 1030562981 | C13: 300 | D13: 50 | E13: 125 | F13: 475 | G13: D/F | H13: 551.94805 | I13: 536.6 | J13: C- | N13: 44.84 | O13: 0 | P13: muy_nuevo | Q13: 0.2
A14: 31918579 | C14: 300 | D14: 150 | E14: 125 | F14: 575 | G14: C | H14: 806.27706 | I14: 760 | J14: B+ | N14: 46.8075 | O14: 0 | P14: muy_nuevo | Q14: 0.2
A15: 1061370725 | C15: 300 | D15: 150 | E15: 125 | F15: 575 | G15: C | H15: 877.70563 | I15: 817.2 | J15: A- | N15: 0 | O15: 0 | P15: muy_nuevo | Q15: 0.2
A16: 1103110446 | C16: 300 | D16: 150 | E16: 125 | F16: 575 | G16: C | H16: 743.50649 | I16: 709.8 | J16: B | N16: 32.610629 | O16: 0 | P16: muy_nuevo | Q16: 0.2
A17: 1221984588 | C17: 300 | D17: 100 | E17: 125 | F17: 525 | G17: C- | H17: 722.94372 | I17: 683.4 | J17: B- | N17: 0 | O17: 0 | P17: muy_nuevo | Q17: 0.2
A18: 52050844 | C18: 300 | D18: 150 | E18: 125 | F18: 575 | G18: C | H18: 860.38961 | I18: 803.3 | J18: A- | N18: 58.7312 | O18: 0 | P18: muy_nuevo | Q18: 0.2
A19: 1010006115 | C19: 300 | D19: 150 | E19: 125 | F19: 575 | G19: C | H19: 823.59307 | I19: 773.9 | J19: B+ | N19: 72.545 | O19: 0 | P19: muy_nuevo | Q19: 0.2
A20: 38611636 | C20: 300 | D20: 150 | E20: 125 | F20: 575 | G20: C | H20: 846.32035 | I20: 792.1 | J20: B+ | N20: 87.985486 | O20: 0 | P20: muy_nuevo | Q20: 0.2
A21: 1121935853 | C21: 300 | D21: 150 | E21: 125 | F21: 575 | G21: C | H21: 737.01299 | I21: 704.6 | J21: B | N21: 0 | O21: 0 | P21: muy_nuevo | Q21: 0.2
A22: 1116548884 | C22: 300 | D22: 150 | E22: 125 | F22: 575 | G22: C | H22: 799.78355 | I22: 754.8 | J22: B+ | N22: 0 | O22: 0 | P22: muy_nuevo | Q22: 0.2
A23: 31330526 | C23: 300 | D23: 150 | E23: 125 | F23: 575 | G23: C | H23: 844.15584 | I23: 790.3 | J23: B+ | N23: 28.70985 | O23: 0 | P23: muy_nuevo | Q23: 0.2
A24: 901809312 | C24: 300 | D24: 100 | E24: 125 | F24: 525 | G24: C- | I24: 525 | J24: C- | N24: 73.2617 | O24: 0 | P24: muy_nuevo | Q24: 1
A25: 31643878 | C25: 300 | D25: 150 | E25: 125 | F25: 575 | G25: C | H25: 829.00433 | I25: 778.2 | J25: B+ | N25: 45.06 | O25: 0 | P25: muy_nuevo | Q25: 0.2
A26: 1062962938 | C26: 300 | D26: 100 | E26: 125 | F26: 525 | G26: C- | H26: 611.47186 | I26: 594.2 | J26: C | N26: 99.6264 | O26: 0 | P26: muy_nuevo | Q26: 0.2
A27: 1005977778 | C27: 300 | D27: 150 | E27: 125 | F27: 575 | G27: C | H27: 792.20779 | I27: 748.8 | J27: B | N27: 93.2132 | O27: 0 | P27: muy_nuevo | Q27: 0.2
A28: 1117807143 | C28: 300 | D28: 150 | E28: 125 | F28: 575 | G28: C | H28: 773.80952 | I28: 734 | J28: B | N28: 29.54665 | O28: 0 | P28: muy_nuevo | Q28: 0.2
A29: 1144097358 | C29: 300 | D29: 100 | E29: 125 | F29: 525 | G29: C- | H29: 687.22944 | I29: 654.8 | J29: B- | N29: 0 | O29: 0 | P29: muy_nuevo | Q29: 0.2
A30: 901932123 | C30: 300 | D30: 100 | E30: 125 | F30: 525 | G30: C- | I30: 525 | J30: C- | N30: 67.6 | O30: 0 | P30: muy_nuevo | Q30: 1
A31: 1074417997 | C31: 300 | D31: 100 | E31: 125 | F31: 525 | G31: C- | H31: 718.61472 | I31: 679.9 | J31: B- | N31: 85.7 | O31: 0 | P31: muy_nuevo | Q31: 0.2
A32: 901256954 | C32: 300 | D32: 100 | E32: 125 | F32: 525 | G32: C- | I32: 525 | J32: C- | N32: 29.372525 | O32: 0 | P32: muy_nuevo | Q32: 1
A33: 12685947 | C33: 300 | D33: 150 | E33: 125 | F33: 575 | G33: C | H33: 865.80087 | I33: 807.6 | J33: A- | N33: 0 | O33: 0 | P33: muy_nuevo | Q33: 0.2
A34: 1093221482 | C34: 300 | D34: 150 | E34: 125 | F34: 575 | G34: C | H34: 836.58009 | I34: 784.3 | J34: B+ | N34: 19.253675 | O34: 0 | P34: muy_nuevo | Q34: 0.2
A35: 72239768 | C35: 300 | D35: 100 | E35: 125 | F35: 525 | G35: C- | H35: 761.90476 | I35: 714.5 | J35: B | N35: 16.460525 | O35: 0 | P35: muy_nuevo | Q35: 0.2
A36: 72151403 | C36: 300 | D36: 150 | E36: 125 | F36: 575 | G36: C | H36: 822.51082 | I36: 773 | J36: B+ | N36: 95.999733 | O36: 0 | P36: muy_nuevo | Q36: 0.2
A37: 1001181877 | C37: 300 | D37: 150 | E37: 125 | F37: 575 | G37: C | H37: 786.79654 | I37: 744.4 | J37: B | N37: 0 | O37: 0 | P37: muy_nuevo | Q37: 0.2
A38: 1013619220 | C38: 300 | D38: 100 | E38: 125 | F38: 525 | G38: C- | I38: 525 | J38: C- | N38: 80 | O38: 0 | P38: muy_nuevo | Q38: 1
A39: 1117325921 | C39: 300 | D39: 100 | E39: 125 | F39: 525 | G39: C- | H39: 764.06926 | I39: 716.3 | J39: B | N39: 47.58455 | O39: 0 | P39: muy_nuevo | Q39: 0.2
A40: 52189031 | C40: 300 | D40: 100 | E40: 125 | F40: 525 | G40: C- | H40: 835.49784 | I40: 773.4 | J40: B+ | N40: 23.0858 | O40: 0 | P40: muy_nuevo | Q40: 0.2
...

Sheet 🎯 Scores Simulados
A1: ID Cliente | B1: Nombre | C1: Comp 1 (Base) | D1: Comp 2 (Base) | E1: Comp 3 (Base) | F1: Comp 1 (Simulado) | G1: Comp 2 (Simulado) | H1: Comp 3 (Simulado) | I1: Score Base | J1: Penalizaciones | K1: Bonificaciones | L1: Score Simulado PLATAM | M1: Score HCPN | N1: Peso PLATAM | O1: Peso HCPN | P1: Score Híbrido Simulado | Q1: Rating Simulado | R1: Cambio vs Base
A2: ='📊 Datos Originales'!A2 | B2: ='📊 Datos Originales'!B2 | C2: ='📊 Datos Originales'!C2 | D2: ='📊 Datos Originales'!D2 | E2: ='📊 Datos Originales'!E2 | F2: =(C2/600)*'🎛️ PANEL DE CONTROL'!B6 | G2: =(D2/150)*'🎛️ PANEL DE CONTROL'!B7 | H2: =(E2/250)*'🎛️ PANEL DE CONTROL'!B8 | I2: =F2+G2+H2 | J2: ==IF('📊 Datos Originales'!L2>30, '🎛️ PANEL DE CONTROL'!B13, 0)+=IF('📊 Datos Originales'!N2>80, '🎛️ PANEL DE CONTROL'!B15, 0) | K2: ==IF('📊 Datos Originales'!M2<10, '🎛️ PANEL DE CONTROL'!B14, 0)+=IF('📊 Datos Originales'!O2>24, '🎛️ PANEL DE CONTROL'!B16, 0) | L2: =MAX(0, MIN(1000, I2-J2+K2)) | M2: ='📊 Datos Originales'!H2 | N2: =IF('📊 Datos Originales'!P2="muy_nuevo", '🎛️ PANEL DE CONTROL'!B20, IF('📊 Datos Originales'!P2="nuevo", '🎛️ PANEL DE CONTROL'!B21, IF('📊 Datos Originales'!P2="intermedio", '🎛️ PANEL DE CONTROL'!B22, IF('📊 Datos Originales'!P2="establecido", '🎛️ PANEL DE CONTROL'!B23, '🎛️ PANEL DE CONTROL'!B24)))) | O2: =1-N2 | P2: =(L2*N2)+(M2*O2) | Q2: =IF(P2>='🎛️ PANEL DE CONTROL'!B28, "A+", IF(P2>='🎛️ PANEL DE CONTROL'!B29, "A", IF(P2>='🎛️ PANEL DE CONTROL'!B30, "A-", IF(P2>='🎛️ PANEL DE CONTROL'!B31, "B+", IF(P2>='🎛️ PANEL DE CONTROL'!B32, "B", IF(P2>='🎛️ PANEL DE CONTROL'!B33, "B-", IF(P2>='🎛️ PANEL DE CONTROL'!B34, "C+", IF(P2>='🎛️ PANEL DE CONTROL'!B35, "C", IF(P2>='🎛️ PANEL DE CONTROL'!B36, "C-", IF(P2>='🎛️ PANEL DE CONTROL'!B37, "D", "F")))))))))) | R2: =P2-'📊 Datos Originales'!I2
A3: ='📊 Datos Originales'!A3 | B3: ='📊 Datos Originales'!B3 | C3: ='📊 Datos Originales'!C3 | D3: ='📊 Datos Originales'!D3 | E3: ='📊 Datos Originales'!E3 | F3: =(C3/600)*'🎛️ PANEL DE CONTROL'!B6 | G3: =(D3/150)*'🎛️ PANEL DE CONTROL'!B7 | H3: =(E3/250)*'🎛️ PANEL DE CONTROL'!B8 | I3: =F3+G3+H3 | J3: ==IF('📊 Datos Originales'!L3>30, '🎛️ PANEL DE CONTROL'!B13, 0)+=IF('📊 Datos Originales'!N3>80, '🎛️ PANEL DE CONTROL'!B15, 0) | K3: ==IF('📊 Datos Originales'!M3<10, '🎛️ PANEL DE CONTROL'!B14, 0)+=IF('📊 Datos Originales'!O3>24, '🎛️ PANEL DE CONTROL'!B16, 0) | L3: =MAX(0, MIN(1000, I3-J3+K3)) | M3: ='📊 Datos Originales'!H3 | N3: =IF('📊 Datos Originales'!P3="muy_nuevo", '🎛️ PANEL DE CONTROL'!B20, IF('📊 Datos Originales'!P3="nuevo", '🎛️ PANEL DE CONTROL'!B21, IF('📊 Datos Originales'!P3="intermedio", '🎛️ PANEL DE CONTROL'!B22, IF('📊 Datos Originales'!P3="establecido", '🎛️ PANEL DE CONTROL'!B23, '🎛️ PANEL DE CONTROL'!B24)))) | O3: =1-N3 | P3: =(L3*N3)+(M3*O3) | Q3: =IF(P3>='🎛️ PANEL DE CONTROL'!B28, "A+", IF(P3>='🎛️ PANEL DE CONTROL'!B29, "A", IF(P3>='🎛️ PANEL DE CONTROL'!B30, "A-", IF(P3>='🎛️ PANEL DE CONTROL'!B31, "B+", IF(P3>='🎛️ PANEL DE CONTROL'!B32, "B", IF(P3>='🎛️ PANEL DE CONTROL'!B33, "B-", IF(P3>='🎛️ PANEL DE CONTROL'!B34, "C+", IF(P3>='🎛️ PANEL DE CONTROL'!B35, "C", IF(P3>='🎛️ PANEL DE CONTROL'!B36, "C-", IF(P3>='🎛️ PANEL DE CONTROL'!B37, "D", "F")))))))))) | R3: =P3-'📊 Datos Originales'!I3
A4: ='📊 Datos Originales'!A4 | B4: ='📊 Datos Originales'!B4 | C4: ='📊 Datos Originales'!C4 | D4: ='📊 Datos Originales'!D4 | E4: ='📊 Datos Originales'!E4 | F4: =(C4/600)*'🎛️ PANEL DE CONTROL'!B6 | G4: =(D4/150)*'🎛️ PANEL DE CONTROL'!B7 | H4: =(E4/250)*'🎛️ PANEL DE CONTROL'!B8 | I4: =F4+G4+H4 | J4: ==IF('📊 Datos Originales'!L4>30, '🎛️ PANEL DE CONTROL'!B13, 0)+=IF('📊 Datos Originales'!N4>80, '🎛️ PANEL DE CONTROL'!B15, 0) | K4: ==IF('📊 Datos Originales'!M4<10, '🎛️ PANEL DE CONTROL'!B14, 0)+=IF('📊 Datos Originales'!O4>24, '🎛️ PANEL DE CONTROL'!B16, 0) | L4: =MAX(0, MIN(1000, I4-J4+K4)) | M4: ='📊 Datos Originales'!H4 | N4: =IF('📊 Datos Originales'!P4="muy_nuevo", '🎛️ PANEL DE CONTROL'!B20, IF('📊 Datos Originales'!P4="nuevo", '🎛️ PANEL DE CONTROL'!B21, IF('📊 Datos Originales'!P4="intermedio", '🎛️ PANEL DE CONTROL'!B22, IF('📊 Datos Originales'!P4="establecido", '🎛️ PANEL DE CONTROL'!B23, '🎛️ PANEL DE CONTROL'!B24)))) | O4: =1-N4 | P4: =(L4*N4)+(M4*O4) | Q4: =IF(P4>='🎛️ PANEL DE CONTROL'!B28, "A+", IF(P4>='🎛️ PANEL DE CONTROL'!B29, "A", IF(P4>='🎛️ PANEL DE CONTROL'!B30, "A-", IF(P4>='🎛️ PANEL DE CONTROL'!B31, "B+", IF(P4>='🎛️ PANEL DE CONTROL'!B32, "B", IF(P4>='🎛️ PANEL DE CONTROL'!B33, "B-", IF(P4>='🎛️ PANEL DE CONTROL'!B34, "C+", IF(P4>='🎛️ PANEL DE CONTROL'!B35, "C", IF(P4>='🎛️ PANEL DE CONTROL'!B36, "C-", IF(P4>='🎛️ PANEL DE CONTROL'!B37, "D", "F")))))))))) | R4: =P4-'📊 Datos Originales'!I4
A5: ='📊 Datos Originales'!A5 | B5: ='📊 Datos Originales'!B5 | C5: ='📊 Datos Originales'!C5 | D5: ='📊 Datos Originales'!D5 | E5: ='📊 Datos Originales'!E5 | F5: =(C5/600)*'🎛️ PANEL DE CONTROL'!B6 | G5: =(D5/150)*'🎛️ PANEL DE CONTROL'!B7 | H5: =(E5/250)*'🎛️ PANEL DE CONTROL'!B8 | I5: =F5+G5+H5 | J5: ==IF('📊 Datos Originales'!L5>30, '🎛️ PANEL DE CONTROL'!B13, 0)+=IF('📊 Datos Originales'!N5>80, '🎛️ PANEL DE CONTROL'!B15, 0) | K5: ==IF('📊 Datos Originales'!M5<10, '🎛️ PANEL DE CONTROL'!B14, 0)+=IF('📊 Datos Originales'!O5>24, '🎛️ PANEL DE CONTROL'!B16, 0) | L5: =MAX(0, MIN(1000, I5-J5+K5)) | M5: ='📊 Datos Originales'!H5 | N5: =IF('📊 Datos Originales'!P5="muy_nuevo", '🎛️ PANEL DE CONTROL'!B20, IF('📊 Datos Originales'!P5="nuevo", '🎛️ PANEL DE CONTROL'!B21, IF('📊 Datos Originales'!P5="intermedio", '🎛️ PANEL DE CONTROL'!B22, IF('📊 Datos Originales'!P5="establecido", '🎛️ PANEL DE CONTROL'!B23, '🎛️ PANEL DE CONTROL'!B24)))) | O5: =1-N5 | P5: =(L5*N5)+(M5*O5) | Q5: =IF(P5>='🎛️ PANEL DE CONTROL'!B28, "A+", IF(P5>='🎛️ PANEL DE CONTROL'!B29, "A", IF(P5>='🎛️ PANEL DE CONTROL'!B30, "A-", IF(P5>='🎛️ PANEL DE CONTROL'!B31, "B+", IF(P5>='🎛️ PANEL DE CONTROL'!B32, "B", IF(P5>='🎛️ PANEL DE CONTROL'!B33, "B-", IF(P5>='🎛️ PANEL DE CONTROL'!B34, "C+", IF(P5>='🎛️ PANEL DE CONTROL'!B35, "C", IF(P5>='🎛️ PANEL DE CONTROL'!B36, "C-", IF(P5>='🎛️ PANEL DE CONTROL'!B37, "D", "F")))))))))) | R5: =P5-'📊 Datos Originales'!I5
A6: ='📊 Datos Originales'!A6 | B6: ='📊 Datos Originales'!B6 | C6: ='📊 Datos Originales'!C6 | D6: ='📊 Datos Originales'!D6 | E6: ='📊 Datos Originales'!E6 | F6: =(C6/600)*'🎛️ PANEL DE CONTROL'!B6 | G6: =(D6/150)*'🎛️ PANEL DE CONTROL'!B7 | H6: =(E6/250)*'🎛️ PANEL DE CONTROL'!B8 | I6: =F6+G6+H6 | J6: ==IF('📊 Datos Originales'!L6>30, '🎛️ PANEL DE CONTROL'!B13, 0)+=IF('📊 Datos Originales'!N6>80, '🎛️ PANEL DE CONTROL'!B15, 0) | K6: ==IF('📊 Datos Originales'!M6<10, '🎛️ PANEL DE CONTROL'!B14, 0)+=IF('📊 Datos Originales'!O6>24, '🎛️ PANEL DE CONTROL'!B16, 0) | L6: =MAX(0, MIN(1000, I6-J6+K6)) | M6: ='📊 Datos Originales'!H6 | N6: =IF('📊 Datos Originales'!P6="muy_nuevo", '🎛️ PANEL DE CONTROL'!B20, IF('📊 Datos Originales'!P6="nuevo", '🎛️ PANEL DE CONTROL'!B21, IF('📊 Datos Originales'!P6="intermedio", '🎛️ PANEL DE CONTROL'!B22, IF('📊 Datos Originales'!P6="establecido", '🎛️ PANEL DE CONTROL'!B23, '🎛️ PANEL DE CONTROL'!B24)))) | O6: =1-N6 | P6: =(L6*N6)+(M6*O6) | Q6: =IF(P6>='🎛️ PANEL DE CONTROL'!B28, "A+", IF(P6>='🎛️ PANEL DE CONTROL'!B29, "A", IF(P6>='🎛️ PANEL DE CONTROL'!B30, "A-", IF(P6>='🎛️ PANEL DE CONTROL'!B31, "B+", IF(P6>='🎛️ PANEL DE CONTROL'!B32, "B", IF(P6>='🎛️ PANEL DE CONTROL'!B33, "B-", IF(P6>='🎛️ PANEL DE CONTROL'!B34, "C+", IF(P6>='🎛️ PANEL DE CONTROL'!B35, "C", IF(P6>='🎛️ PANEL DE CONTROL'!B36, "C-", IF(P6>='🎛️ PANEL DE CONTROL'!B37, "D", "F")))))))))) | R6: =P6-'📊 Datos Originales'!I6
A7: ='📊 Datos Originales'!A7 | B7: ='📊 Datos Originales'!B7 | C7: ='📊 Datos Originales'!C7 | D7: ='📊 Datos Originales'!D7 | E7: ='📊 Datos Originales'!E7 | F7: =(C7/600)*'🎛️ PANEL DE CONTROL'!B6 | G7: =(D7/150)*'🎛️ PANEL DE CONTROL'!B7 | H7: =(E7/250)*'🎛️ PANEL DE CONTROL'!B8 | I7: =F7+G7+H7 | J7: ==IF('📊 Datos Originales'!L7>30, '🎛️ PANEL DE CONTROL'!B13, 0)+=IF('📊 Datos Originales'!N7>80, '🎛️ PANEL DE CONTROL'!B15, 0) | K7: ==IF('📊 Datos Originales'!M7<10, '🎛️ PANEL DE CONTROL'!B14, 0)+=IF('📊 Datos Originales'!O7>24, '🎛️ PANEL DE CONTROL'!B16, 0) | L7: =MAX(0, MIN(1000, I7-J7+K7)) | M7: ='📊 Datos Originales'!H7 | N7: =IF('📊 Datos Originales'!P7="muy_nuevo", '🎛️ PANEL DE CONTROL'!B20, IF('📊 Datos Originales'!P7="nuevo", '🎛️ PANEL DE CONTROL'!B21, IF('📊 Datos Originales'!P7="intermedio", '🎛️ PANEL DE CONTROL'!B22, IF('📊 Datos Originales'!P7="establecido", '🎛️ PANEL DE CONTROL'!B23, '🎛️ PANEL DE CONTROL'!B24)))) | O7: =1-N7 | P7: =(L7*N7)+(M7*O7) | Q7: =IF(P7>='🎛️ PANEL DE CONTROL'!B28, "A+", IF(P7>='🎛️ PANEL DE CONTROL'!B29, "A", IF(P7>='🎛️ PANEL DE CONTROL'!B30, "A-", IF(P7>='🎛️ PANEL DE CONTROL'!B31, "B+", IF(P7>='🎛️ PANEL DE CONTROL'!B32, "B", IF(P7>='🎛️ PANEL DE CONTROL'!B33, "B-", IF(P7>='🎛️ PANEL DE CONTROL'!B34, "C+", IF(P7>='🎛️ PANEL DE CONTROL'!B35, "C", IF(P7>='🎛️ PANEL DE CONTROL'!B36, "C-", IF(P7>='🎛️ PANEL DE CONTROL'!B37, "D", "F")))))))))) | R7: =P7-'📊 Datos Originales'!I7
A8: ='📊 Datos Originales'!A8 | B8: ='📊 Datos Originales'!B8 | C8: ='📊 Datos Originales'!C8 | D8: ='📊 Datos Originales'!D8 | E8: ='📊 Datos Originales'!E8 | F8: =(C8/600)*'🎛️ PANEL DE CONTROL'!B6 | G8: =(D8/150)*'🎛️ PANEL DE CONTROL'!B7 | H8: =(E8/250)*'🎛️ PANEL DE CONTROL'!B8 | I8: =F8+G8+H8 | J8: ==IF('📊 Datos Originales'!L8>30, '🎛️ PANEL DE CONTROL'!B13, 0)+=IF('📊 Datos Originales'!N8>80, '🎛️ PANEL DE CONTROL'!B15, 0) | K8: ==IF('📊 Datos Originales'!M8<10, '🎛️ PANEL DE CONTROL'!B14, 0)+=IF('📊 Datos Originales'!O8>24, '🎛️ PANEL DE CONTROL'!B16, 0) | L8: =MAX(0, MIN(1000, I8-J8+K8)) | M8: ='📊 Datos Originales'!H8 | N8: =IF('📊 Datos Originales'!P8="muy_nuevo", '🎛️ PANEL DE CONTROL'!B20, IF('📊 Datos Originales'!P8="nuevo", '🎛️ PANEL DE CONTROL'!B21, IF('📊 Datos Originales'!P8="intermedio", '🎛️ PANEL DE CONTROL'!B22, IF('📊 Datos Originales'!P8="establecido", '🎛️ PANEL DE CONTROL'!B23, '🎛️ PANEL DE CONTROL'!B24)))) | O8: =1-N8 | P8: =(L8*N8)+(M8*O8) | Q8: =IF(P8>='🎛️ PANEL DE CONTROL'!B28, "A+", IF(P8>='🎛️ PANEL DE CONTROL'!B29, "A", IF(P8>='🎛️ PANEL DE CONTROL'!B30, "A-", IF(P8>='🎛️ PANEL DE CONTROL'!B31, "B+", IF(P8>='🎛️ PANEL DE CONTROL'!B32, "B", IF(P8>='🎛️ PANEL DE CONTROL'!B33, "B-", IF(P8>='🎛️ PANEL DE CONTROL'!B34, "C+", IF(P8>='🎛️ PANEL DE CONTROL'!B35, "C", IF(P8>='🎛️ PANEL DE CONTROL'!B36, "C-", IF(P8>='🎛️ PANEL DE CONTROL'!B37, "D", "F")))))))))) | R8: =P8-'📊 Datos Originales'!I8
A9: ='📊 Datos Originales'!A9 | B9: ='📊 Datos Originales'!B9 | C9: ='📊 Datos Originales'!C9 | D9: ='📊 Datos Originales'!D9 | E9: ='📊 Datos Originales'!E9 | F9: =(C9/600)*'🎛️ PANEL DE CONTROL'!B6 | G9: =(D9/150)*'🎛️ PANEL DE CONTROL'!B7 | H9: =(E9/250)*'🎛️ PANEL DE CONTROL'!B8 | I9: =F9+G9+H9 | J9: ==IF('📊 Datos Originales'!L9>30, '🎛️ PANEL DE CONTROL'!B13, 0)+=IF('📊 Datos Originales'!N9>80, '🎛️ PANEL DE CONTROL'!B15, 0) | K9: ==IF('📊 Datos Originales'!M9<10, '🎛️ PANEL DE CONTROL'!B14, 0)+=IF('📊 Datos Originales'!O9>24, '🎛️ PANEL DE CONTROL'!B16, 0) | L9: =MAX(0, MIN(1000, I9-J9+K9)) | M9: ='📊 Datos Originales'!H9 | N9: =IF('📊 Datos Originales'!P9="muy_nuevo", '🎛️ PANEL DE CONTROL'!B20, IF('📊 Datos Originales'!P9="nuevo", '🎛️ PANEL DE CONTROL'!B21, IF('📊 Datos Originales'!P9="intermedio", '🎛️ PANEL DE CONTROL'!B22, IF('📊 Datos Originales'!P9="establecido", '🎛️ PANEL DE CONTROL'!B23, '🎛️ PANEL DE CONTROL'!B24)))) | O9: =1-N9 | P9: =(L9*N9)+(M9*O9) | Q9: =IF(P9>='🎛️ PANEL DE CONTROL'!B28, "A+", IF(P9>='🎛️ PANEL DE CONTROL'!B29, "A", IF(P9>='🎛️ PANEL DE CONTROL'!B30, "A-", IF(P9>='🎛️ PANEL DE CONTROL'!B31, "B+", IF(P9>='🎛️ PANEL DE CONTROL'!B32, "B", IF(P9>='🎛️ PANEL DE CONTROL'!B33, "B-", IF(P9>='🎛️ PANEL DE CONTROL'!B34, "C+", IF(P9>='🎛️ PANEL DE CONTROL'!B35, "C", IF(P9>='🎛️ PANEL DE CONTROL'!B36, "C-", IF(P9>='🎛️ PANEL DE CONTROL'!B37, "D", "F")))))))))) | R9: =P9-'📊 Datos Originales'!I9
A10: ='📊 Datos Originales'!A10 | B10: ='📊 Datos Originales'!B10 | C10: ='📊 Datos Originales'!C10 | D10: ='📊 Datos Originales'!D10 | E10: ='📊 Datos Originales'!E10 | F10: =(C10/600)*'🎛️ PANEL DE CONTROL'!B6 | G10: =(D10/150)*'🎛️ PANEL DE CONTROL'!B7 | H10: =(E10/250)*'🎛️ PANEL DE CONTROL'!B8 | I10: =F10+G10+H10 | J10: ==IF('📊 Datos Originales'!L10>30, '🎛️ PANEL DE CONTROL'!B13, 0)+=IF('📊 Datos Originales'!N10>80, '🎛️ PANEL DE CONTROL'!B15, 0) | K10: ==IF('📊 Datos Originales'!M10<10, '🎛️ PANEL DE CONTROL'!B14, 0)+=IF('📊 Datos Originales'!O10>24, '🎛️ PANEL DE CONTROL'!B16, 0) | L10: =MAX(0, MIN(1000, I10-J10+K10)) | M10: ='📊 Datos Originales'!H10 | N10: =IF('📊 Datos Originales'!P10="muy_nuevo", '🎛️ PANEL DE CONTROL'!B20, IF('📊 Datos Originales'!P10="nuevo", '🎛️ PANEL DE CONTROL'!B21, IF('📊 Datos Originales'!P10="intermedio", '🎛️ PANEL DE CONTROL'!B22, IF('📊 Datos Originales'!P10="establecido", '🎛️ PANEL DE CONTROL'!B23, '🎛️ PANEL DE CONTROL'!B24)))) | O10: =1-N10 | P10: =(L10*N10)+(M10*O10) | Q10: =IF(P10>='🎛️ PANEL DE CONTROL'!B28, "A+", IF(P10>='🎛️ PANEL DE CONTROL'!B29, "A", IF(P10>='🎛️ PANEL DE CONTROL'!B30, "A-", IF(P10>='🎛️ PANEL DE CONTROL'!B31, "B+", IF(P10>='🎛️ PANEL DE CONTROL'!B32, "B", IF(P10>='🎛️ PANEL DE CONTROL'!B33, "B-", IF(P10>='🎛️ PANEL DE CONTROL'!B34, "C+", IF(P10>='🎛️ PANEL DE CONTROL'!B35, "C", IF(P10>='🎛️ PANEL DE CONTROL'!B36, "C-", IF(P10>='🎛️ PANEL DE CONTROL'!B37, "D", "F")))))))))) | R10: =P10-'📊 Datos Originales'!I10
A11: ='📊 Datos Originales'!A11 | B11: ='📊 Datos Originales'!B11 | C11: ='📊 Datos Originales'!C11 | D11: ='📊 Datos Originales'!D11 | E11: ='📊 Datos Originales'!E11 | F11: =(C11/600)*'🎛️ PANEL DE CONTROL'!B6 | G11: =(D11/150)*'🎛️ PANEL DE CONTROL'!B7 | H11: =(E11/250)*'🎛️ PANEL DE CONTROL'!B8 | I11: =F11+G11+H11 | J11: ==IF('📊 Datos Originales'!L11>30, '🎛️ PANEL DE CONTROL'!B13, 0)+=IF('📊 Datos Originales'!N11>80, '🎛️ PANEL DE CONTROL'!B15, 0) | K11: ==IF('📊 Datos Originales'!M11<10, '🎛️ PANEL DE CONTROL'!B14, 0)+=IF('📊 Datos Originales'!O11>24, '🎛️ PANEL DE CONTROL'!B16, 0) | L11: =MAX(0, MIN(1000, I11-J11+K11)) | M11: ='📊 Datos Originales'!H11 | N11: =IF('📊 Datos Originales'!P11="muy_nuevo", '🎛️ PANEL DE CONTROL'!B20, IF('📊 Datos Originales'!P11="nuevo", '🎛️ PANEL DE CONTROL'!B21, IF('📊 Datos Originales'!P11="intermedio", '🎛️ PANEL DE CONTROL'!B22, IF('📊 Datos Originales'!P11="establecido", '🎛️ PANEL DE CONTROL'!B23, '🎛️ PANEL DE CONTROL'!B24)))) | O11: =1-N11 | P11: =(L11*N11)+(M11*O11) | Q11: =IF(P11>='🎛️ PANEL DE CONTROL'!B28, "A+", IF(P11>='🎛️ PANEL DE CONTROL'!B29, "A", IF(P11>='🎛️ PANEL DE CONTROL'!B30, "A-", IF(P11>='🎛️ PANEL DE CONTROL'!B31, "B+", IF(P11>='🎛️ PANEL DE CONTROL'!B32, "B", IF(P11>='🎛️ PANEL DE CONTROL'!B33, "B-", IF(P11>='🎛️ PANEL DE CONTROL'!B34, "C+", IF(P11>='🎛️ PANEL DE CONTROL'!B35, "C", IF(P11>='🎛️ PANEL DE CONTROL'!B36, "C-", IF(P11>='🎛️ PANEL DE CONTROL'!B37, "D", "F")))))))))) | R11: =P11-'📊 Datos Originales'!I11
A12: ='📊 Datos Originales'!A12 | B12: ='📊 Datos Originales'!B12 | C12: ='📊 Datos Originales'!C12 | D12: ='📊 Datos Originales'!D12 | E12: ='📊 Datos Originales'!E12 | F12: =(C12/600)*'🎛️ PANEL DE CONTROL'!B6 | G12: =(D12/150)*'🎛️ PANEL DE CONTROL'!B7 | H12: =(E12/250)*'🎛️ PANEL DE CONTROL'!B8 | I12: =F12+G12+H12 | J12: ==IF('📊 Datos Originales'!L12>30, '🎛️ PANEL DE CONTROL'!B13, 0)+=IF('📊 Datos Originales'!N12>80, '🎛️ PANEL DE CONTROL'!B15, 0) | K12: ==IF('📊 Datos Originales'!M12<10, '🎛️ PANEL DE CONTROL'!B14, 0)+=IF('📊 Datos Originales'!O12>24, '🎛️ PANEL DE CONTROL'!B16, 0) | L12: =MAX(0, MIN(1000, I12-J12+K12)) | M12: ='📊 Datos Originales'!H12 | N12: =IF('📊 Datos Originales'!P12="muy_nuevo", '🎛️ PANEL DE CONTROL'!B20, IF('📊 Datos Originales'!P12="nuevo", '🎛️ PANEL DE CONTROL'!B21, IF('📊 Datos Originales'!P12="intermedio", '🎛️ PANEL DE CONTROL'!B22, IF('📊 Datos Originales'!P12="establecido", '🎛️ PANEL DE CONTROL'!B23, '🎛️ PANEL DE CONTROL'!B24)))) | O12: =1-N12 | P12: =(L12*N12)+(M12*O12) | Q12: =IF(P12>='🎛️ PANEL DE CONTROL'!B28, "A+", IF(P12>='🎛️ PANEL DE CONTROL'!B29, "A", IF(P12>='🎛️ PANEL DE CONTROL'!B30, "A-", IF(P12>='🎛️ PANEL DE CONTROL'!B31, "B+", IF(P12>='🎛️ PANEL DE CONTROL'!B32, "B", IF(P12>='🎛️ PANEL DE CONTROL'!B33, "B-", IF(P12>='🎛️ PANEL DE CONTROL'!B34, "C+", IF(P12>='🎛️ PANEL DE CONTROL'!B35, "C", IF(P12>='🎛️ PANEL DE CONTROL'!B36, "C-", IF(P12>='🎛️ PANEL DE CONTROL'!B37, "D", "F")))))))))) | R12: =P12-'📊 Datos Originales'!I12
A13: ='📊 Datos Originales'!A13 | B13: ='📊 Datos Originales'!B13 | C13: ='📊 Datos Originales'!C13 | D13: ='📊 Datos Originales'!D13 | E13: ='📊 Datos Originales'!E13 | F13: =(C13/600)*'🎛️ PANEL DE CONTROL'!B6 | G13: =(D13/150)*'🎛️ PANEL DE CONTROL'!B7 | H13: =(E13/250)*'🎛️ PANEL DE CONTROL'!B8 | I13: =F13+G13+H13 | J13: ==IF('📊 Datos Originales'!L13>30, '🎛️ PANEL DE CONTROL'!B13, 0)+=IF('📊 Datos Originales'!N13>80, '🎛️ PANEL DE CONTROL'!B15, 0) | K13: ==IF('📊 Datos Originales'!M13<10, '🎛️ PANEL DE CONTROL'!B14, 0)+=IF('📊 Datos Originales'!O13>24, '🎛️ PANEL DE CONTROL'!B16, 0) | L13: =MAX(0, MIN(1000, I13-J13+K13)) | M13: ='📊 Datos Originales'!H13 | N13: =IF('📊 Datos Originales'!P13="muy_nuevo", '🎛️ PANEL DE CONTROL'!B20, IF('📊 Datos Originales'!P13="nuevo", '🎛️ PANEL DE CONTROL'!B21, IF('📊 Datos Originales'!P13="intermedio", '🎛️ PANEL DE CONTROL'!B22, IF('📊 Datos Originales'!P13="establecido", '🎛️ PANEL DE CONTROL'!B23, '🎛️ PANEL DE CONTROL'!B24)))) | O13: =1-N13 | P13: =(L13*N13)+(M13*O13) | Q13: =IF(P13>='🎛️ PANEL DE CONTROL'!B28, "A+", IF(P13>='🎛️ PANEL DE CONTROL'!B29, "A", IF(P13>='🎛️ PANEL DE CONTROL'!B30, "A-", IF(P13>='🎛️ PANEL DE CONTROL'!B31, "B+", IF(P13>='🎛️ PANEL DE CONTROL'!B32, "B", IF(P13>='🎛️ PANEL DE CONTROL'!B33, "B-", IF(P13>='🎛️ PANEL DE CONTROL'!B34, "C+", IF(P13>='🎛️ PANEL DE CONTROL'!B35, "C", IF(P13>='🎛️ PANEL DE CONTROL'!B36, "C-", IF(P13>='🎛️ PANEL DE CONTROL'!B37, "D", "F")))))))))) | R13: =P13-'📊 Datos Originales'!I13
A14: ='📊 Datos Originales'!A14 | B14: ='📊 Datos Originales'!B14 | C14: ='📊 Datos Originales'!C14 | D14: ='📊 Datos Originales'!D14 | E14: ='📊 Datos Originales'!E14 | F14: =(C14/600)*'🎛️ PANEL DE CONTROL'!B6 | G14: =(D14/150)*'🎛️ PANEL DE CONTROL'!B7 | H14: =(E14/250)*'🎛️ PANEL DE CONTROL'!B8 | I14: =F14+G14+H14 | J14: ==IF('📊 Datos Originales'!L14>30, '🎛️ PANEL DE CONTROL'!B13, 0)+=IF('📊 Datos Originales'!N14>80, '🎛️ PANEL DE CONTROL'!B15, 0) | K14: ==IF('📊 Datos Originales'!M14<10, '🎛️ PANEL DE CONTROL'!B14, 0)+=IF('📊 Datos Originales'!O14>24, '🎛️ PANEL DE CONTROL'!B16, 0) | L14: =MAX(0, MIN(1000, I14-J14+K14)) | M14: ='📊 Datos Originales'!H14 | N14: =IF('📊 Datos Originales'!P14="muy_nuevo", '🎛️ PANEL DE CONTROL'!B20, IF('📊 Datos Originales'!P14="nuevo", '🎛️ PANEL DE CONTROL'!B21, IF('📊 Datos Originales'!P14="intermedio", '🎛️ PANEL DE CONTROL'!B22, IF('📊 Datos Originales'!P14="establecido", '🎛️ PANEL DE CONTROL'!B23, '🎛️ PANEL DE CONTROL'!B24)))) | O14: =1-N14 | P14: =(L14*N14)+(M14*O14) | Q14: =IF(P14>='🎛️ PANEL DE CONTROL'!B28, "A+", IF(P14>='🎛️ PANEL DE CONTROL'!B29, "A", IF(P14>='🎛️ PANEL DE CONTROL'!B30, "A-", IF(P14>='🎛️ PANEL DE CONTROL'!B31, "B+", IF(P14>='🎛️ PANEL DE CONTROL'!B32, "B", IF(P14>='🎛️ PANEL DE CONTROL'!B33, "B-", IF(P14>='🎛️ PANEL DE CONTROL'!B34, "C+", IF(P14>='🎛️ PANEL DE CONTROL'!B35, "C", IF(P14>='🎛️ PANEL DE CONTROL'!B36, "C-", IF(P14>='🎛️ PANEL DE CONTROL'!B37, "D", "F")))))))))) | R14: =P14-'📊 Datos Originales'!I14
A15: ='📊 Datos Originales'!A15 | B15: ='📊 Datos Originales'!B15 | C15: ='📊 Datos Originales'!C15 | D15: ='📊 Datos Originales'!D15 | E15: ='📊 Datos Originales'!E15 | F15: =(C15/600)*'🎛️ PANEL DE CONTROL'!B6 | G15: =(D15/150)*'🎛️ PANEL DE CONTROL'!B7 | H15: =(E15/250)*'🎛️ PANEL DE CONTROL'!B8 | I15: =F15+G15+H15 | J15: ==IF('📊 Datos Originales'!L15>30, '🎛️ PANEL DE CONTROL'!B13, 0)+=IF('📊 Datos Originales'!N15>80, '🎛️ PANEL DE CONTROL'!B15, 0) | K15: ==IF('📊 Datos Originales'!M15<10, '🎛️ PANEL DE CONTROL'!B14, 0)+=IF('📊 Datos Originales'!O15>24, '🎛️ PANEL DE CONTROL'!B16, 0) | L15: =MAX(0, MIN(1000, I15-J15+K15)) | M15: ='📊 Datos Originales'!H15 | N15: =IF('📊 Datos Originales'!P15="muy_nuevo", '🎛️ PANEL DE CONTROL'!B20, IF('📊 Datos Originales'!P15="nuevo", '🎛️ PANEL DE CONTROL'!B21, IF('📊 Datos Originales'!P15="intermedio", '🎛️ PANEL DE CONTROL'!B22, IF('📊 Datos Originales'!P15="establecido", '🎛️ PANEL DE CONTROL'!B23, '🎛️ PANEL DE CONTROL'!B24)))) | O15: =1-N15 | P15: =(L15*N15)+(M15*O15) | Q15: =IF(P15>='🎛️ PANEL DE CONTROL'!B28, "A+", IF(P15>='🎛️ PANEL DE CONTROL'!B29, "A", IF(P15>='🎛️ PANEL DE CONTROL'!B30, "A-", IF(P15>='🎛️ PANEL DE CONTROL'!B31, "B+", IF(P15>='🎛️ PANEL DE CONTROL'!B32, "B", IF(P15>='🎛️ PANEL DE CONTROL'!B33, "B-", IF(P15>='🎛️ PANEL DE CONTROL'!B34, "C+", IF(P15>='🎛️ PANEL DE CONTROL'!B35, "C", IF(P15>='🎛️ PANEL DE CONTROL'!B36, "C-", IF(P15>='🎛️ PANEL DE CONTROL'!B37, "D", "F")))))))))) | R15: =P15-'📊 Datos Originales'!I15
A16: ='📊 Datos Originales'!A16 | B16: ='📊 Datos Originales'!B16 | C16: ='📊 Datos Originales'!C16 | D16: ='📊 Datos Originales'!D16 | E16: ='📊 Datos Originales'!E16 | F16: =(C16/600)*'🎛️ PANEL DE CONTROL'!B6 | G16: =(D16/150)*'🎛️ PANEL DE CONTROL'!B7 | H16: =(E16/250)*'🎛️ PANEL DE CONTROL'!B8 | I16: =F16+G16+H16 | J16: ==IF('📊 Datos Originales'!L16>30, '🎛️ PANEL DE CONTROL'!B13, 0)+=IF('📊 Datos Originales'!N16>80, '🎛️ PANEL DE CONTROL'!B15, 0) | K16: ==IF('📊 Datos Originales'!M16<10, '🎛️ PANEL DE CONTROL'!B14, 0)+=IF('📊 Datos Originales'!O16>24, '🎛️ PANEL DE CONTROL'!B16, 0) | L16: =MAX(0, MIN(1000, I16-J16+K16)) | M16: ='📊 Datos Originales'!H16 | N16: =IF('📊 Datos Originales'!P16="muy_nuevo", '🎛️ PANEL DE CONTROL'!B20, IF('📊 Datos Originales'!P16="nuevo", '🎛️ PANEL DE CONTROL'!B21, IF('📊 Datos Originales'!P16="intermedio", '🎛️ PANEL DE CONTROL'!B22, IF('📊 Datos Originales'!P16="establecido", '🎛️ PANEL DE CONTROL'!B23, '🎛️ PANEL DE CONTROL'!B24)))) | O16: =1-N16 | P16: =(L16*N16)+(M16*O16) | Q16: =IF(P16>='🎛️ PANEL DE CONTROL'!B28, "A+", IF(P16>='🎛️ PANEL DE CONTROL'!B29, "A", IF(P16>='🎛️ PANEL DE CONTROL'!B30, "A-", IF(P16>='🎛️ PANEL DE CONTROL'!B31, "B+", IF(P16>='🎛️ PANEL DE CONTROL'!B32, "B", IF(P16>='🎛️ PANEL DE CONTROL'!B33, "B-", IF(P16>='🎛️ PANEL DE CONTROL'!B34, "C+", IF(P16>='🎛️ PANEL DE CONTROL'!B35, "C", IF(P16>='🎛️ PANEL DE CONTROL'!B36, "C-", IF(P16>='🎛️ PANEL DE CONTROL'!B37, "D", "F")))))))))) | R16: =P16-'📊 Datos Originales'!I16
A17: ='📊 Datos Originales'!A17 | B17: ='📊 Datos Originales'!B17 | C17: ='📊 Datos Originales'!C17 | D17: ='📊 Datos Originales'!D17 | E17: ='📊 Datos Originales'!E17 | F17: =(C17/600)*'🎛️ PANEL DE CONTROL'!B6 | G17: =(D17/150)*'🎛️ PANEL DE CONTROL'!B7 | H17: =(E17/250)*'🎛️ PANEL DE CONTROL'!B8 | I17: =F17+G17+H17 | J17: ==IF('📊 Datos Originales'!L17>30, '🎛️ PANEL DE CONTROL'!B13, 0)+=IF('📊 Datos Originales'!N17>80, '🎛️ PANEL DE CONTROL'!B15, 0) | K17: ==IF('📊 Datos Originales'!M17<10, '🎛️ PANEL DE CONTROL'!B14, 0)+=IF('📊 Datos Originales'!O17>24, '🎛️ PANEL DE CONTROL'!B16, 0) | L17: =MAX(0, MIN(1000, I17-J17+K17)) | M17: ='📊 Datos Originales'!H17 | N17: =IF('📊 Datos Originales'!P17="muy_nuevo", '🎛️ PANEL DE CONTROL'!B20, IF('📊 Datos Originales'!P17="nuevo", '🎛️ PANEL DE CONTROL'!B21, IF('📊 Datos Originales'!P17="intermedio", '🎛️ PANEL DE CONTROL'!B22, IF('📊 Datos Originales'!P17="establecido", '🎛️ PANEL DE CONTROL'!B23, '🎛️ PANEL DE CONTROL'!B24)))) | O17: =1-N17 | P17: =(L17*N17)+(M17*O17) | Q17: =IF(P17>='🎛️ PANEL DE CONTROL'!B28, "A+", IF(P17>='🎛️ PANEL DE CONTROL'!B29, "A", IF(P17>='🎛️ PANEL DE CONTROL'!B30, "A-", IF(P17>='🎛️ PANEL DE CONTROL'!B31, "B+", IF(P17>='🎛️ PANEL DE CONTROL'!B32, "B", IF(P17>='🎛️ PANEL DE CONTROL'!B33, "B-", IF(P17>='🎛️ PANEL DE CONTROL'!B34, "C+", IF(P17>='🎛️ PANEL DE CONTROL'!B35, "C", IF(P17>='🎛️ PANEL DE CONTROL'!B36, "C-", IF(P17>='🎛️ PANEL DE CONTROL'!B37, "D", "F")))))))))) | R17: =P17-'📊 Datos Originales'!I17
A18: ='📊 Datos Originales'!A18 | B18: ='📊 Datos Originales'!B18 | C18: ='📊 Datos Originales'!C18 | D18: ='📊 Datos Originales'!D18 | E18: ='📊 Datos Originales'!E18 | F18: =(C18/600)*'🎛️ PANEL DE CONTROL'!B6 | G18: =(D18/150)*'🎛️ PANEL DE CONTROL'!B7 | H18: =(E18/250)*'🎛️ PANEL DE CONTROL'!B8 | I18: =F18+G18+H18 | J18: ==IF('📊 Datos Originales'!L18>30, '🎛️ PANEL DE CONTROL'!B13, 0)+=IF('📊 Datos Originales'!N18>80, '🎛️ PANEL DE CONTROL'!B15, 0) | K18: ==IF('📊 Datos Originales'!M18<10, '🎛️ PANEL DE CONTROL'!B14, 0)+=IF('📊 Datos Originales'!O18>24, '🎛️ PANEL DE CONTROL'!B16, 0) | L18: =MAX(0, MIN(1000, I18-J18+K18)) | M18: ='📊 Datos Originales'!H18 | N18: =IF('📊 Datos Originales'!P18="muy_nuevo", '🎛️ PANEL DE CONTROL'!B20, IF('📊 Datos Originales'!P18="nuevo", '🎛️ PANEL DE CONTROL'!B21, IF('📊 Datos Originales'!P18="intermedio", '🎛️ PANEL DE CONTROL'!B22, IF('📊 Datos Originales'!P18="establecido", '🎛️ PANEL DE CONTROL'!B23, '🎛️ PANEL DE CONTROL'!B24)))) | O18: =1-N18 | P18: =(L18*N18)+(M18*O18) | Q18: =IF(P18>='🎛️ PANEL DE CONTROL'!B28, "A+", IF(P18>='🎛️ PANEL DE CONTROL'!B29, "A", IF(P18>='🎛️ PANEL DE CONTROL'!B30, "A-", IF(P18>='🎛️ PANEL DE CONTROL'!B31, "B+", IF(P18>='🎛️ PANEL DE CONTROL'!B32, "B", IF(P18>='🎛️ PANEL DE CONTROL'!B33, "B-", IF(P18>='🎛️ PANEL DE CONTROL'!B34, "C+", IF(P18>='🎛️ PANEL DE CONTROL'!B35, "C", IF(P18>='🎛️ PANEL DE CONTROL'!B36, "C-", IF(P18>='🎛️ PANEL DE CONTROL'!B37, "D", "F")))))))))) | R18: =P18-'📊 Datos Originales'!I18
A19: ='📊 Datos Originales'!A19 | B19: ='📊 Datos Originales'!B19 | C19: ='📊 Datos Originales'!C19 | D19: ='📊 Datos Originales'!D19 | E19: ='📊 Datos Originales'!E19 | F19: =(C19/600)*'🎛️ PANEL DE CONTROL'!B6 | G19: =(D19/150)*'🎛️ PANEL DE CONTROL'!B7 | H19: =(E19/250)*'🎛️ PANEL DE CONTROL'!B8 | I19: =F19+G19+H19 | J19: ==IF('📊 Datos Originales'!L19>30, '🎛️ PANEL DE CONTROL'!B13, 0)+=IF('📊 Datos Originales'!N19>80, '🎛️ PANEL DE CONTROL'!B15, 0) | K19: ==IF('📊 Datos Originales'!M19<10, '🎛️ PANEL DE CONTROL'!B14, 0)+=IF('📊 Datos Originales'!O19>24, '🎛️ PANEL DE CONTROL'!B16, 0) | L19: =MAX(0, MIN(1000, I19-J19+K19)) | M19: ='📊 Datos Originales'!H19 | N19: =IF('📊 Datos Originales'!P19="muy_nuevo", '🎛️ PANEL DE CONTROL'!B20, IF('📊 Datos Originales'!P19="nuevo", '🎛️ PANEL DE CONTROL'!B21, IF('📊 Datos Originales'!P19="intermedio", '🎛️ PANEL DE CONTROL'!B22, IF('📊 Datos Originales'!P19="establecido", '🎛️ PANEL DE CONTROL'!B23, '🎛️ PANEL DE CONTROL'!B24)))) | O19: =1-N19 | P19: =(L19*N19)+(M19*O19) | Q19: =IF(P19>='🎛️ PANEL DE CONTROL'!B28, "A+", IF(P19>='🎛️ PANEL DE CONTROL'!B29, "A", IF(P19>='🎛️ PANEL DE CONTROL'!B30, "A-", IF(P19>='🎛️ PANEL DE CONTROL'!B31, "B+", IF(P19>='🎛️ PANEL DE CONTROL'!B32, "B", IF(P19>='🎛️ PANEL DE CONTROL'!B33, "B-", IF(P19>='🎛️ PANEL DE CONTROL'!B34, "C+", IF(P19>='🎛️ PANEL DE CONTROL'!B35, "C", IF(P19>='🎛️ PANEL DE CONTROL'!B36, "C-", IF(P19>='🎛️ PANEL DE CONTROL'!B37, "D", "F")))))))))) | R19: =P19-'📊 Datos Originales'!I19
A20: ='📊 Datos Originales'!A20 | B20: ='📊 Datos Originales'!B20 | C20: ='📊 Datos Originales'!C20 | D20: ='📊 Datos Originales'!D20 | E20: ='📊 Datos Originales'!E20 | F20: =(C20/600)*'🎛️ PANEL DE CONTROL'!B6 | G20: =(D20/150)*'🎛️ PANEL DE CONTROL'!B7 | H20: =(E20/250)*'🎛️ PANEL DE CONTROL'!B8 | I20: =F20+G20+H20 | J20: ==IF('📊 Datos Originales'!L20>30, '🎛️ PANEL DE CONTROL'!B13, 0)+=IF('📊 Datos Originales'!N20>80, '🎛️ PANEL DE CONTROL'!B15, 0) | K20: ==IF('📊 Datos Originales'!M20<10, '🎛️ PANEL DE CONTROL'!B14, 0)+=IF('📊 Datos Originales'!O20>24, '🎛️ PANEL DE CONTROL'!B16, 0) | L20: =MAX(0, MIN(1000, I20-J20+K20)) | M20: ='📊 Datos Originales'!H20 | N20: =IF('📊 Datos Originales'!P20="muy_nuevo", '🎛️ PANEL DE CONTROL'!B20, IF('📊 Datos Originales'!P20="nuevo", '🎛️ PANEL DE CONTROL'!B21, IF('📊 Datos Originales'!P20="intermedio", '🎛️ PANEL DE CONTROL'!B22, IF('📊 Datos Originales'!P20="establecido", '🎛️ PANEL DE CONTROL'!B23, '🎛️ PANEL DE CONTROL'!B24)))) | O20: =1-N20 | P20: =(L20*N20)+(M20*O20) | Q20: =IF(P20>='🎛️ PANEL DE CONTROL'!B28, "A+", IF(P20>='🎛️ PANEL DE CONTROL'!B29, "A", IF(P20>='🎛️ PANEL DE CONTROL'!B30, "A-", IF(P20>='🎛️ PANEL DE CONTROL'!B31, "B+", IF(P20>='🎛️ PANEL DE CONTROL'!B32, "B", IF(P20>='🎛️ PANEL DE CONTROL'!B33, "B-", IF(P20>='🎛️ PANEL DE CONTROL'!B34, "C+", IF(P20>='🎛️ PANEL DE CONTROL'!B35, "C", IF(P20>='🎛️ PANEL DE CONTROL'!B36, "C-", IF(P20>='🎛️ PANEL DE CONTROL'!B37, "D", "F")))))))))) | R20: =P20-'📊 Datos Originales'!I20
A21: ='📊 Datos Originales'!A21 | B21: ='📊 Datos Originales'!B21 | C21: ='📊 Datos Originales'!C21 | D21: ='📊 Datos Originales'!D21 | E21: ='📊 Datos Originales'!E21 | F21: =(C21/600)*'🎛️ PANEL DE CONTROL'!B6 | G21: =(D21/150)*'🎛️ PANEL DE CONTROL'!B7 | H21: =(E21/250)*'🎛️ PANEL DE CONTROL'!B8 | I21: =F21+G21+H21 | J21: ==IF('📊 Datos Originales'!L21>30, '🎛️ PANEL DE CONTROL'!B13, 0)+=IF('📊 Datos Originales'!N21>80, '🎛️ PANEL DE CONTROL'!B15, 0) | K21: ==IF('📊 Datos Originales'!M21<10, '🎛️ PANEL DE CONTROL'!B14, 0)+=IF('📊 Datos Originales'!O21>24, '🎛️ PANEL DE CONTROL'!B16, 0) | L21: =MAX(0, MIN(1000, I21-J21+K21)) | M21: ='📊 Datos Originales'!H21 | N21: =IF('📊 Datos Originales'!P21="muy_nuevo", '🎛️ PANEL DE CONTROL'!B20, IF('📊 Datos Originales'!P21="nuevo", '🎛️ PANEL DE CONTROL'!B21, IF('📊 Datos Originales'!P21="intermedio", '🎛️ PANEL DE CONTROL'!B22, IF('📊 Datos Originales'!P21="establecido", '🎛️ PANEL DE CONTROL'!B23, '🎛️ PANEL DE CONTROL'!B24)))) | O21: =1-N21 | P21: =(L21*N21)+(M21*O21) | Q21: =IF(P21>='🎛️ PANEL DE CONTROL'!B28, "A+", IF(P21>='🎛️ PANEL DE CONTROL'!B29, "A", IF(P21>='🎛️ PANEL DE CONTROL'!B30, "A-", IF(P21>='🎛️ PANEL DE CONTROL'!B31, "B+", IF(P21>='🎛️ PANEL DE CONTROL'!B32, "B", IF(P21>='🎛️ PANEL DE CONTROL'!B33, "B-", IF(P21>='🎛️ PANEL DE CONTROL'!B34, "C+", IF(P21>='🎛️ PANEL DE CONTROL'!B35, "C", IF(P21>='🎛️ PANEL DE CONTROL'!B36, "C-", IF(P21>='🎛️ PANEL DE CONTROL'!B37, "D", "F")))))))))) | R21: =P21-'📊 Datos Originales'!I21
A22: ='📊 Datos Originales'!A22 | B22: ='📊 Datos Originales'!B22 | C22: ='📊 Datos Originales'!C22 | D22: ='📊 Datos Originales'!D22 | E22: ='📊 Datos Originales'!E22 | F22: =(C22/600)*'🎛️ PANEL DE CONTROL'!B6 | G22: =(D22/150)*'🎛️ PANEL DE CONTROL'!B7 | H22: =(E22/250)*'🎛️ PANEL DE CONTROL'!B8 | I22: =F22+G22+H22 | J22: ==IF('📊 Datos Originales'!L22>30, '🎛️ PANEL DE CONTROL'!B13, 0)+=IF('📊 Datos Originales'!N22>80, '🎛️ PANEL DE CONTROL'!B15, 0) | K22: ==IF('📊 Datos Originales'!M22<10, '🎛️ PANEL DE CONTROL'!B14, 0)+=IF('📊 Datos Originales'!O22>24, '🎛️ PANEL DE CONTROL'!B16, 0) | L22: =MAX(0, MIN(1000, I22-J22+K22)) | M22: ='📊 Datos Originales'!H22 | N22: =IF('📊 Datos Originales'!P22="muy_nuevo", '🎛️ PANEL DE CONTROL'!B20, IF('📊 Datos Originales'!P22="nuevo", '🎛️ PANEL DE CONTROL'!B21, IF('📊 Datos Originales'!P22="intermedio", '🎛️ PANEL DE CONTROL'!B22, IF('📊 Datos Originales'!P22="establecido", '🎛️ PANEL DE CONTROL'!B23, '🎛️ PANEL DE CONTROL'!B24)))) | O22: =1-N22 | P22: =(L22*N22)+(M22*O22) | Q22: =IF(P22>='🎛️ PANEL DE CONTROL'!B28, "A+", IF(P22>='🎛️ PANEL DE CONTROL'!B29, "A", IF(P22>='🎛️ PANEL DE CONTROL'!B30, "A-", IF(P22>='🎛️ PANEL DE CONTROL'!B31, "B+", IF(P22>='🎛️ PANEL DE CONTROL'!B32, "B", IF(P22>='🎛️ PANEL DE CONTROL'!B33, "B-", IF(P22>='🎛️ PANEL DE CONTROL'!B34, "C+", IF(P22>='🎛️ PANEL DE CONTROL'!B35, "C", IF(P22>='🎛️ PANEL DE CONTROL'!B36, "C-", IF(P22>='🎛️ PANEL DE CONTROL'!B37, "D", "F")))))))))) | R22: =P22-'📊 Datos Originales'!I22
A23: ='📊 Datos Originales'!A23 | B23: ='📊 Datos Originales'!B23 | C23: ='📊 Datos Originales'!C23 | D23: ='📊 Datos Originales'!D23 | E23: ='📊 Datos Originales'!E23 | F23: =(C23/600)*'🎛️ PANEL DE CONTROL'!B6 | G23: =(D23/150)*'🎛️ PANEL DE CONTROL'!B7 | H23: =(E23/250)*'🎛️ PANEL DE CONTROL'!B8 | I23: =F23+G23+H23 | J23: ==IF('📊 Datos Originales'!L23>30, '🎛️ PANEL DE CONTROL'!B13, 0)+=IF('📊 Datos Originales'!N23>80, '🎛️ PANEL DE CONTROL'!B15, 0) | K23: ==IF('📊 Datos Originales'!M23<10, '🎛️ PANEL DE CONTROL'!B14, 0)+=IF('📊 Datos Originales'!O23>24, '🎛️ PANEL DE CONTROL'!B16, 0) | L23: =MAX(0, MIN(1000, I23-J23+K23)) | M23: ='📊 Datos Originales'!H23 | N23: =IF('📊 Datos Originales'!P23="muy_nuevo", '🎛️ PANEL DE CONTROL'!B20, IF('📊 Datos Originales'!P23="nuevo", '🎛️ PANEL DE CONTROL'!B21, IF('📊 Datos Originales'!P23="intermedio", '🎛️ PANEL DE CONTROL'!B22, IF('📊 Datos Originales'!P23="establecido", '🎛️ PANEL DE CONTROL'!B23, '🎛️ PANEL DE CONTROL'!B24)))) | O23: =1-N23 | P23: =(L23*N23)+(M23*O23) | Q23: =IF(P23>='🎛️ PANEL DE CONTROL'!B28, "A+", IF(P23>='🎛️ PANEL DE CONTROL'!B29, "A", IF(P23>='🎛️ PANEL DE CONTROL'!B30, "A-", IF(P23>='🎛️ PANEL DE CONTROL'!B31, "B+", IF(P23>='🎛️ PANEL DE CONTROL'!B32, "B", IF(P23>='🎛️ PANEL DE CONTROL'!B33, "B-", IF(P23>='🎛️ PANEL DE CONTROL'!B34, "C+", IF(P23>='🎛️ PANEL DE CONTROL'!B35, "C", IF(P23>='🎛️ PANEL DE CONTROL'!B36, "C-", IF(P23>='🎛️ PANEL DE CONTROL'!B37, "D", "F")))))))))) | R23: =P23-'📊 Datos Originales'!I23
A24: ='📊 Datos Originales'!A24 | B24: ='📊 Datos Originales'!B24 | C24: ='📊 Datos Originales'!C24 | D24: ='📊 Datos Originales'!D24 | E24: ='📊 Datos Originales'!E24 | F24: =(C24/600)*'🎛️ PANEL DE CONTROL'!B6 | G24: =(D24/150)*'🎛️ PANEL DE CONTROL'!B7 | H24: =(E24/250)*'🎛️ PANEL DE CONTROL'!B8 | I24: =F24+G24+H24 | J24: ==IF('📊 Datos Originales'!L24>30, '🎛️ PANEL DE CONTROL'!B13, 0)+=IF('📊 Datos Originales'!N24>80, '🎛️ PANEL DE CONTROL'!B15, 0) | K24: ==IF('📊 Datos Originales'!M24<10, '🎛️ PANEL DE CONTROL'!B14, 0)+=IF('📊 Datos Originales'!O24>24, '🎛️ PANEL DE CONTROL'!B16, 0) | L24: =MAX(0, MIN(1000, I24-J24+K24)) | M24: ='📊 Datos Originales'!H24 | N24: =IF('📊 Datos Originales'!P24="muy_nuevo", '🎛️ PANEL DE CONTROL'!B20, IF('📊 Datos Originales'!P24="nuevo", '🎛️ PANEL DE CONTROL'!B21, IF('📊 Datos Originales'!P24="intermedio", '🎛️ PANEL DE CONTROL'!B22, IF('📊 Datos Originales'!P24="establecido", '🎛️ PANEL DE CONTROL'!B23, '🎛️ PANEL DE CONTROL'!B24)))) | O24: =1-N24 | P24: =(L24*N24)+(M24*O24) | Q24: =IF(P24>='🎛️ PANEL DE CONTROL'!B28, "A+", IF(P24>='🎛️ PANEL DE CONTROL'!B29, "A", IF(P24>='🎛️ PANEL DE CONTROL'!B30, "A-", IF(P24>='🎛️ PANEL DE CONTROL'!B31, "B+", IF(P24>='🎛️ PANEL DE CONTROL'!B32, "B", IF(P24>='🎛️ PANEL DE CONTROL'!B33, "B-", IF(P24>='🎛️ PANEL DE CONTROL'!B34, "C+", IF(P24>='🎛️ PANEL DE CONTROL'!B35, "C", IF(P24>='🎛️ PANEL DE CONTROL'!B36, "C-", IF(P24>='🎛️ PANEL DE CONTROL'!B37, "D", "F")))))))))) | R24: =P24-'📊 Datos Originales'!I24
A25: ='📊 Datos Originales'!A25 | B25: ='📊 Datos Originales'!B25 | C25: ='📊 Datos Originales'!C25 | D25: ='📊 Datos Originales'!D25 | E25: ='📊 Datos Originales'!E25 | F25: =(C25/600)*'🎛️ PANEL DE CONTROL'!B6 | G25: =(D25/150)*'🎛️ PANEL DE CONTROL'!B7 | H25: =(E25/250)*'🎛️ PANEL DE CONTROL'!B8 | I25: =F25+G25+H25 | J25: ==IF('📊 Datos Originales'!L25>30, '🎛️ PANEL DE CONTROL'!B13, 0)+=IF('📊 Datos Originales'!N25>80, '🎛️ PANEL DE CONTROL'!B15, 0) | K25: ==IF('📊 Datos Originales'!M25<10, '🎛️ PANEL DE CONTROL'!B14, 0)+=IF('📊 Datos Originales'!O25>24, '🎛️ PANEL DE CONTROL'!B16, 0) | L25: =MAX(0, MIN(1000, I25-J25+K25)) | M25: ='📊 Datos Originales'!H25 | N25: =IF('📊 Datos Originales'!P25="muy_nuevo", '🎛️ PANEL DE CONTROL'!B20, IF('📊 Datos Originales'!P25="nuevo", '🎛️ PANEL DE CONTROL'!B21, IF('📊 Datos Originales'!P25="intermedio", '🎛️ PANEL DE CONTROL'!B22, IF('📊 Datos Originales'!P25="establecido", '🎛️ PANEL DE CONTROL'!B23, '🎛️ PANEL DE CONTROL'!B24)))) | O25: =1-N25 | P25: =(L25*N25)+(M25*O25) | Q25: =IF(P25>='🎛️ PANEL DE CONTROL'!B28, "A+", IF(P25>='🎛️ PANEL DE CONTROL'!B29, "A", IF(P25>='🎛️ PANEL DE CONTROL'!B30, "A-", IF(P25>='🎛️ PANEL DE CONTROL'!B31, "B+", IF(P25>='🎛️ PANEL DE CONTROL'!B32, "B", IF(P25>='🎛️ PANEL DE CONTROL'!B33, "B-", IF(P25>='🎛️ PANEL DE CONTROL'!B34, "C+", IF(P25>='🎛️ PANEL DE CONTROL'!B35, "C", IF(P25>='🎛️ PANEL DE CONTROL'!B36, "C-", IF(P25>='🎛️ PANEL DE CONTROL'!B37, "D", "F")))))))))) | R25: =P25-'📊 Datos Originales'!I25
A26: ='📊 Datos Originales'!A26 | B26: ='📊 Datos Originales'!B26 | C26: ='📊 Datos Originales'!C26 | D26: ='📊 Datos Originales'!D26 | E26: ='📊 Datos Originales'!E26 | F26: =(C26/600)*'🎛️ PANEL DE CONTROL'!B6 | G26: =(D26/150)*'🎛️ PANEL DE CONTROL'!B7 | H26: =(E26/250)*'🎛️ PANEL DE CONTROL'!B8 | I26: =F26+G26+H26 | J26: ==IF('📊 Datos Originales'!L26>30, '🎛️ PANEL DE CONTROL'!B13, 0)+=IF('📊 Datos Originales'!N26>80, '🎛️ PANEL DE CONTROL'!B15, 0) | K26: ==IF('📊 Datos Originales'!M26<10, '🎛️ PANEL DE CONTROL'!B14, 0)+=IF('📊 Datos Originales'!O26>24, '🎛️ PANEL DE CONTROL'!B16, 0) | L26: =MAX(0, MIN(1000, I26-J26+K26)) | M26: ='📊 Datos Originales'!H26 | N26: =IF('📊 Datos Originales'!P26="muy_nuevo", '🎛️ PANEL DE CONTROL'!B20, IF('📊 Datos Originales'!P26="nuevo", '🎛️ PANEL DE CONTROL'!B21, IF('📊 Datos Originales'!P26="intermedio", '🎛️ PANEL DE CONTROL'!B22, IF('📊 Datos Originales'!P26="establecido", '🎛️ PANEL DE CONTROL'!B23, '🎛️ PANEL DE CONTROL'!B24)))) | O26: =1-N26 | P26: =(L26*N26)+(M26*O26) | Q26: =IF(P26>='🎛️ PANEL DE CONTROL'!B28, "A+", IF(P26>='🎛️ PANEL DE CONTROL'!B29, "A", IF(P26>='🎛️ PANEL DE CONTROL'!B30, "A-", IF(P26>='🎛️ PANEL DE CONTROL'!B31, "B+", IF(P26>='🎛️ PANEL DE CONTROL'!B32, "B", IF(P26>='🎛️ PANEL DE CONTROL'!B33, "B-", IF(P26>='🎛️ PANEL DE CONTROL'!B34, "C+", IF(P26>='🎛️ PANEL DE CONTROL'!B35, "C", IF(P26>='🎛️ PANEL DE CONTROL'!B36, "C-", IF(P26>='🎛️ PANEL DE CONTROL'!B37, "D", "F")))))))))) | R26: =P26-'📊 Datos Originales'!I26
A27: ='📊 Datos Originales'!A27 | B27: ='📊 Datos Originales'!B27 | C27: ='📊 Datos Originales'!C27 | D27: ='📊 Datos Originales'!D27 | E27: ='📊 Datos Originales'!E27 | F27: =(C27/600)*'🎛️ PANEL DE CONTROL'!B6 | G27: =(D27/150)*'🎛️ PANEL DE CONTROL'!B7 | H27: =(E27/250)*'🎛️ PANEL DE CONTROL'!B8 | I27: =F27+G27+H27 | J27: ==IF('📊 Datos Originales'!L27>30, '🎛️ PANEL DE CONTROL'!B13, 0)+=IF('📊 Datos Originales'!N27>80, '🎛️ PANEL DE CONTROL'!B15, 0) | K27: ==IF('📊 Datos Originales'!M27<10, '🎛️ PANEL DE CONTROL'!B14, 0)+=IF('📊 Datos Originales'!O27>24, '🎛️ PANEL DE CONTROL'!B16, 0) | L27: =MAX(0, MIN(1000, I27-J27+K27)) | M27: ='📊 Datos Originales'!H27 | N27: =IF('📊 Datos Originales'!P27="muy_nuevo", '🎛️ PANEL DE CONTROL'!B20, IF('📊 Datos Originales'!P27="nuevo", '🎛️ PANEL DE CONTROL'!B21, IF('📊 Datos Originales'!P27="intermedio", '🎛️ PANEL DE CONTROL'!B22, IF('📊 Datos Originales'!P27="establecido", '🎛️ PANEL DE CONTROL'!B23, '🎛️ PANEL DE CONTROL'!B24)))) | O27: =1-N27 | P27: =(L27*N27)+(M27*O27) | Q27: =IF(P27>='🎛️ PANEL DE CONTROL'!B28, "A+", IF(P27>='🎛️ PANEL DE CONTROL'!B29, "A", IF(P27>='🎛️ PANEL DE CONTROL'!B30, "A-", IF(P27>='🎛️ PANEL DE CONTROL'!B31, "B+", IF(P27>='🎛️ PANEL DE CONTROL'!B32, "B", IF(P27>='🎛️ PANEL DE CONTROL'!B33, "B-", IF(P27>='🎛️ PANEL DE CONTROL'!B34, "C+", IF(P27>='🎛️ PANEL DE CONTROL'!B35, "C", IF(P27>='🎛️ PANEL DE CONTROL'!B36, "C-", IF(P27>='🎛️ PANEL DE CONTROL'!B37, "D", "F")))))))))) | R27: =P27-'📊 Datos Originales'!I27
A28: ='📊 Datos Originales'!A28 | B28: ='📊 Datos Originales'!B28 | C28: ='📊 Datos Originales'!C28 | D28: ='📊 Datos Originales'!D28 | E28: ='📊 Datos Originales'!E28 | F28: =(C28/600)*'🎛️ PANEL DE CONTROL'!B6 | G28: =(D28/150)*'🎛️ PANEL DE CONTROL'!B7 | H28: =(E28/250)*'🎛️ PANEL DE CONTROL'!B8 | I28: =F28+G28+H28 | J28: ==IF('📊 Datos Originales'!L28>30, '🎛️ PANEL DE CONTROL'!B13, 0)+=IF('📊 Datos Originales'!N28>80, '🎛️ PANEL DE CONTROL'!B15, 0) | K28: ==IF('📊 Datos Originales'!M28<10, '🎛️ PANEL DE CONTROL'!B14, 0)+=IF('📊 Datos Originales'!O28>24, '🎛️ PANEL DE CONTROL'!B16, 0) | L28: =MAX(0, MIN(1000, I28-J28+K28)) | M28: ='📊 Datos Originales'!H28 | N28: =IF('📊 Datos Originales'!P28="muy_nuevo", '🎛️ PANEL DE CONTROL'!B20, IF('📊 Datos Originales'!P28="nuevo", '🎛️ PANEL DE CONTROL'!B21, IF('📊 Datos Originales'!P28="intermedio", '🎛️ PANEL DE CONTROL'!B22, IF('📊 Datos Originales'!P28="establecido", '🎛️ PANEL DE CONTROL'!B23, '🎛️ PANEL DE CONTROL'!B24)))) | O28: =1-N28 | P28: =(L28*N28)+(M28*O28) | Q28: =IF(P28>='🎛️ PANEL DE CONTROL'!B28, "A+", IF(P28>='🎛️ PANEL DE CONTROL'!B29, "A", IF(P28>='🎛️ PANEL DE CONTROL'!B30, "A-", IF(P28>='🎛️ PANEL DE CONTROL'!B31, "B+", IF(P28>='🎛️ PANEL DE CONTROL'!B32, "B", IF(P28>='🎛️ PANEL DE CONTROL'!B33, "B-", IF(P28>='🎛️ PANEL DE CONTROL'!B34, "C+", IF(P28>='🎛️ PANEL DE CONTROL'!B35, "C", IF(P28>='🎛️ PANEL DE CONTROL'!B36, "C-", IF(P28>='🎛️ PANEL DE CONTROL'!B37, "D", "F")))))))))) | R28: =P28-'📊 Datos Originales'!I28
A29: ='📊 Datos Originales'!A29 | B29: ='📊 Datos Originales'!B29 | C29: ='📊 Datos Originales'!C29 | D29: ='📊 Datos Originales'!D29 | E29: ='📊 Datos Originales'!E29 | F29: =(C29/600)*'🎛️ PANEL DE CONTROL'!B6 | G29: =(D29/150)*'🎛️ PANEL DE CONTROL'!B7 | H29: =(E29/250)*'🎛️ PANEL DE CONTROL'!B8 | I29: =F29+G29+H29 | J29: ==IF('📊 Datos Originales'!L29>30, '🎛️ PANEL DE CONTROL'!B13, 0)+=IF('📊 Datos Originales'!N29>80, '🎛️ PANEL DE CONTROL'!B15, 0) | K29: ==IF('📊 Datos Originales'!M29<10, '🎛️ PANEL DE CONTROL'!B14, 0)+=IF('📊 Datos Originales'!O29>24, '🎛️ PANEL DE CONTROL'!B16, 0) | L29: =MAX(0, MIN(1000, I29-J29+K29)) | M29: ='📊 Datos Originales'!H29 | N29: =IF('📊 Datos Originales'!P29="muy_nuevo", '🎛️ PANEL DE CONTROL'!B20, IF('📊 Datos Originales'!P29="nuevo", '🎛️ PANEL DE CONTROL'!B21, IF('📊 Datos Originales'!P29="intermedio", '🎛️ PANEL DE CONTROL'!B22, IF('📊 Datos Originales'!P29="establecido", '🎛️ PANEL DE CONTROL'!B23, '🎛️ PANEL DE CONTROL'!B24)))) | O29: =1-N29 | P29: =(L29*N29)+(M29*O29) | Q29: =IF(P29>='🎛️ PANEL DE CONTROL'!B28, "A+", IF(P29>='🎛️ PANEL DE CONTROL'!B29, "A", IF(P29>='🎛️ PANEL DE CONTROL'!B30, "A-", IF(P29>='🎛️ PANEL DE CONTROL'!B31, "B+", IF(P29>='🎛️ PANEL DE CONTROL'!B32, "B", IF(P29>='🎛️ PANEL DE CONTROL'!B33, "B-", IF(P29>='🎛️ PANEL DE CONTROL'!B34, "C+", IF(P29>='🎛️ PANEL DE CONTROL'!B35, "C", IF(P29>='🎛️ PANEL DE CONTROL'!B36, "C-", IF(P29>='🎛️ PANEL DE CONTROL'!B37, "D", "F")))))))))) | R29: =P29-'📊 Datos Originales'!I29
A30: ='📊 Datos Originales'!A30 | B30: ='📊 Datos Originales'!B30 | C30: ='📊 Datos Originales'!C30 | D30: ='📊 Datos Originales'!D30 | E30: ='📊 Datos Originales'!E30 | F30: =(C30/600)*'🎛️ PANEL DE CONTROL'!B6 | G30: =(D30/150)*'🎛️ PANEL DE CONTROL'!B7 | H30: =(E30/250)*'🎛️ PANEL DE CONTROL'!B8 | I30: =F30+G30+H30 | J30: ==IF('📊 Datos Originales'!L30>30, '🎛️ PANEL DE CONTROL'!B13, 0)+=IF('📊 Datos Originales'!N30>80, '🎛️ PANEL DE CONTROL'!B15, 0) | K30: ==IF('📊 Datos Originales'!M30<10, '🎛️ PANEL DE CONTROL'!B14, 0)+=IF('📊 Datos Originales'!O30>24, '🎛️ PANEL DE CONTROL'!B16, 0) | L30: =MAX(0, MIN(1000, I30-J30+K30)) | M30: ='📊 Datos Originales'!H30 | N30: =IF('📊 Datos Originales'!P30="muy_nuevo", '🎛️ PANEL DE CONTROL'!B20, IF('📊 Datos Originales'!P30="nuevo", '🎛️ PANEL DE CONTROL'!B21, IF('📊 Datos Originales'!P30="intermedio", '🎛️ PANEL DE CONTROL'!B22, IF('📊 Datos Originales'!P30="establecido", '🎛️ PANEL DE CONTROL'!B23, '🎛️ PANEL DE CONTROL'!B24)))) | O30: =1-N30 | P30: =(L30*N30)+(M30*O30) | Q30: =IF(P30>='🎛️ PANEL DE CONTROL'!B28, "A+", IF(P30>='🎛️ PANEL DE CONTROL'!B29, "A", IF(P30>='🎛️ PANEL DE CONTROL'!B30, "A-", IF(P30>='🎛️ PANEL DE CONTROL'!B31, "B+", IF(P30>='🎛️ PANEL DE CONTROL'!B32, "B", IF(P30>='🎛️ PANEL DE CONTROL'!B33, "B-", IF(P30>='🎛️ PANEL DE CONTROL'!B34, "C+", IF(P30>='🎛️ PANEL DE CONTROL'!B35, "C", IF(P30>='🎛️ PANEL DE CONTROL'!B36, "C-", IF(P30>='🎛️ PANEL DE CONTROL'!B37, "D", "F")))))))))) | R30: =P30-'📊 Datos Originales'!I30
A31: ='📊 Datos Originales'!A31 | B31: ='📊 Datos Originales'!B31 | C31: ='📊 Datos Originales'!C31 | D31: ='📊 Datos Originales'!D31 | E31: ='📊 Datos Originales'!E31 | F31: =(C31/600)*'🎛️ PANEL DE CONTROL'!B6 | G31: =(D31/150)*'🎛️ PANEL DE CONTROL'!B7 | H31: =(E31/250)*'🎛️ PANEL DE CONTROL'!B8 | I31: =F31+G31+H31 | J31: ==IF('📊 Datos Originales'!L31>30, '🎛️ PANEL DE CONTROL'!B13, 0)+=IF('📊 Datos Originales'!N31>80, '🎛️ PANEL DE CONTROL'!B15, 0) | K31: ==IF('📊 Datos Originales'!M31<10, '🎛️ PANEL DE CONTROL'!B14, 0)+=IF('📊 Datos Originales'!O31>24, '🎛️ PANEL DE CONTROL'!B16, 0) | L31: =MAX(0, MIN(1000, I31-J31+K31)) | M31: ='📊 Datos Originales'!H31 | N31: =IF('📊 Datos Originales'!P31="muy_nuevo", '🎛️ PANEL DE CONTROL'!B20, IF('📊 Datos Originales'!P31="nuevo", '🎛️ PANEL DE CONTROL'!B21, IF('📊 Datos Originales'!P31="intermedio", '🎛️ PANEL DE CONTROL'!B22, IF('📊 Datos Originales'!P31="establecido", '🎛️ PANEL DE CONTROL'!B23, '🎛️ PANEL DE CONTROL'!B24)))) | O31: =1-N31 | P31: =(L31*N31)+(M31*O31) | Q31: =IF(P31>='🎛️ PANEL DE CONTROL'!B28, "A+", IF(P31>='🎛️ PANEL DE CONTROL'!B29, "A", IF(P31>='🎛️ PANEL DE CONTROL'!B30, "A-", IF(P31>='🎛️ PANEL DE CONTROL'!B31, "B+", IF(P31>='🎛️ PANEL DE CONTROL'!B32, "B", IF(P31>='🎛️ PANEL DE CONTROL'!B33, "B-", IF(P31>='🎛️ PANEL DE CONTROL'!B34, "C+", IF(P31>='🎛️ PANEL DE CONTROL'!B35, "C", IF(P31>='🎛️ PANEL DE CONTROL'!B36, "C-", IF(P31>='🎛️ PANEL DE CONTROL'!B37, "D", "F")))))))))) | R31: =P31-'📊 Datos Originales'!I31
A32: ='📊 Datos Originales'!A32 | B32: ='📊 Datos Originales'!B32 | C32: ='📊 Datos Originales'!C32 | D32: ='📊 Datos Originales'!D32 | E32: ='📊 Datos Originales'!E32 | F32: =(C32/600)*'🎛️ PANEL DE CONTROL'!B6 | G32: =(D32/150)*'🎛️ PANEL DE CONTROL'!B7 | H32: =(E32/250)*'🎛️ PANEL DE CONTROL'!B8 | I32: =F32+G32+H32 | J32: ==IF('📊 Datos Originales'!L32>30, '🎛️ PANEL DE CONTROL'!B13, 0)+=IF('📊 Datos Originales'!N32>80, '🎛️ PANEL DE CONTROL'!B15, 0) | K32: ==IF('📊 Datos Originales'!M32<10, '🎛️ PANEL DE CONTROL'!B14, 0)+=IF('📊 Datos Originales'!O32>24, '🎛️ PANEL DE CONTROL'!B16, 0) | L32: =MAX(0, MIN(1000, I32-J32+K32)) | M32: ='📊 Datos Originales'!H32 | N32: =IF('📊 Datos Originales'!P32="muy_nuevo", '🎛️ PANEL DE CONTROL'!B20, IF('📊 Datos Originales'!P32="nuevo", '🎛️ PANEL DE CONTROL'!B21, IF('📊 Datos Originales'!P32="intermedio", '🎛️ PANEL DE CONTROL'!B22, IF('📊 Datos Originales'!P32="establecido", '🎛️ PANEL DE CONTROL'!B23, '🎛️ PANEL DE CONTROL'!B24)))) | O32: =1-N32 | P32: =(L32*N32)+(M32*O32) | Q32: =IF(P32>='🎛️ PANEL DE CONTROL'!B28, "A+", IF(P32>='🎛️ PANEL DE CONTROL'!B29, "A", IF(P32>='🎛️ PANEL DE CONTROL'!B30, "A-", IF(P32>='🎛️ PANEL DE CONTROL'!B31, "B+", IF(P32>='🎛️ PANEL DE CONTROL'!B32, "B", IF(P32>='🎛️ PANEL DE CONTROL'!B33, "B-", IF(P32>='🎛️ PANEL DE CONTROL'!B34, "C+", IF(P32>='🎛️ PANEL DE CONTROL'!B35, "C", IF(P32>='🎛️ PANEL DE CONTROL'!B36, "C-", IF(P32>='🎛️ PANEL DE CONTROL'!B37, "D", "F")))))))))) | R32: =P32-'📊 Datos Originales'!I32
A33: ='📊 Datos Originales'!A33 | B33: ='📊 Datos Originales'!B33 | C33: ='📊 Datos Originales'!C33 | D33: ='📊 Datos Originales'!D33 | E33: ='📊 Datos Originales'!E33 | F33: =(C33/600)*'🎛️ PANEL DE CONTROL'!B6 | G33: =(D33/150)*'🎛️ PANEL DE CONTROL'!B7 | H33: =(E33/250)*'🎛️ PANEL DE CONTROL'!B8 | I33: =F33+G33+H33 | J33: ==IF('📊 Datos Originales'!L33>30, '🎛️ PANEL DE CONTROL'!B13, 0)+=IF('📊 Datos Originales'!N33>80, '🎛️ PANEL DE CONTROL'!B15, 0) | K33: ==IF('📊 Datos Originales'!M33<10, '🎛️ PANEL DE CONTROL'!B14, 0)+=IF('📊 Datos Originales'!O33>24, '🎛️ PANEL DE CONTROL'!B16, 0) | L33: =MAX(0, MIN(1000, I33-J33+K33)) | M33: ='📊 Datos Originales'!H33 | N33: =IF('📊 Datos Originales'!P33="muy_nuevo", '🎛️ PANEL DE CONTROL'!B20, IF('📊 Datos Originales'!P33="nuevo", '🎛️ PANEL DE CONTROL'!B21, IF('📊 Datos Originales'!P33="intermedio", '🎛️ PANEL DE CONTROL'!B22, IF('📊 Datos Originales'!P33="establecido", '🎛️ PANEL DE CONTROL'!B23, '🎛️ PANEL DE CONTROL'!B24)))) | O33: =1-N33 | P33: =(L33*N33)+(M33*O33) | Q33: =IF(P33>='🎛️ PANEL DE CONTROL'!B28, "A+", IF(P33>='🎛️ PANEL DE CONTROL'!B29, "A", IF(P33>='🎛️ PANEL DE CONTROL'!B30, "A-", IF(P33>='🎛️ PANEL DE CONTROL'!B31, "B+", IF(P33>='🎛️ PANEL DE CONTROL'!B32, "B", IF(P33>='🎛️ PANEL DE CONTROL'!B33, "B-", IF(P33>='🎛️ PANEL DE CONTROL'!B34, "C+", IF(P33>='🎛️ PANEL DE CONTROL'!B35, "C", IF(P33>='🎛️ PANEL DE CONTROL'!B36, "C-", IF(P33>='🎛️ PANEL DE CONTROL'!B37, "D", "F")))))))))) | R33: =P33-'📊 Datos Originales'!I33
A34: ='📊 Datos Originales'!A34 | B34: ='📊 Datos Originales'!B34 | C34: ='📊 Datos Originales'!C34 | D34: ='📊 Datos Originales'!D34 | E34: ='📊 Datos Originales'!E34 | F34: =(C34/600)*'🎛️ PANEL DE CONTROL'!B6 | G34: =(D34/150)*'🎛️ PANEL DE CONTROL'!B7 | H34: =(E34/250)*'🎛️ PANEL DE CONTROL'!B8 | I34: =F34+G34+H34 | J34: ==IF('📊 Datos Originales'!L34>30, '🎛️ PANEL DE CONTROL'!B13, 0)+=IF('📊 Datos Originales'!N34>80, '🎛️ PANEL DE CONTROL'!B15, 0) | K34: ==IF('📊 Datos Originales'!M34<10, '🎛️ PANEL DE CONTROL'!B14, 0)+=IF('📊 Datos Originales'!O34>24, '🎛️ PANEL DE CONTROL'!B16, 0) | L34: =MAX(0, MIN(1000, I34-J34+K34)) | M34: ='📊 Datos Originales'!H34 | N34: =IF('📊 Datos Originales'!P34="muy_nuevo", '🎛️ PANEL DE CONTROL'!B20, IF('📊 Datos Originales'!P34="nuevo", '🎛️ PANEL DE CONTROL'!B21, IF('📊 Datos Originales'!P34="intermedio", '🎛️ PANEL DE CONTROL'!B22, IF('📊 Datos Originales'!P34="establecido", '🎛️ PANEL DE CONTROL'!B23, '🎛️ PANEL DE CONTROL'!B24)))) | O34: =1-N34 | P34: =(L34*N34)+(M34*O34) | Q34: =IF(P34>='🎛️ PANEL DE CONTROL'!B28, "A+", IF(P34>='🎛️ PANEL DE CONTROL'!B29, "A", IF(P34>='🎛️ PANEL DE CONTROL'!B30, "A-", IF(P34>='🎛️ PANEL DE CONTROL'!B31, "B+", IF(P34>='🎛️ PANEL DE CONTROL'!B32, "B", IF(P34>='🎛️ PANEL DE CONTROL'!B33, "B-", IF(P34>='🎛️ PANEL DE CONTROL'!B34, "C+", IF(P34>='🎛️ PANEL DE CONTROL'!B35, "C", IF(P34>='🎛️ PANEL DE CONTROL'!B36, "C-", IF(P34>='🎛️ PANEL DE CONTROL'!B37, "D", "F")))))))))) | R34: =P34-'📊 Datos Originales'!I34
A35: ='📊 Datos Originales'!A35 | B35: ='📊 Datos Originales'!B35 | C35: ='📊 Datos Originales'!C35 | D35: ='📊 Datos Originales'!D35 | E35: ='📊 Datos Originales'!E35 | F35: =(C35/600)*'🎛️ PANEL DE CONTROL'!B6 | G35: =(D35/150)*'🎛️ PANEL DE CONTROL'!B7 | H35: =(E35/250)*'🎛️ PANEL DE CONTROL'!B8 | I35: =F35+G35+H35 | J35: ==IF('📊 Datos Originales'!L35>30, '🎛️ PANEL DE CONTROL'!B13, 0)+=IF('📊 Datos Originales'!N35>80, '🎛️ PANEL DE CONTROL'!B15, 0) | K35: ==IF('📊 Datos Originales'!M35<10, '🎛️ PANEL DE CONTROL'!B14, 0)+=IF('📊 Datos Originales'!O35>24, '🎛️ PANEL DE CONTROL'!B16, 0) | L35: =MAX(0, MIN(1000, I35-J35+K35)) | M35: ='📊 Datos Originales'!H35 | N35: =IF('📊 Datos Originales'!P35="muy_nuevo", '🎛️ PANEL DE CONTROL'!B20, IF('📊 Datos Originales'!P35="nuevo", '🎛️ PANEL DE CONTROL'!B21, IF('📊 Datos Originales'!P35="intermedio", '🎛️ PANEL DE CONTROL'!B22, IF('📊 Datos Originales'!P35="establecido", '🎛️ PANEL DE CONTROL'!B23, '🎛️ PANEL DE CONTROL'!B24)))) | O35: =1-N35 | P35: =(L35*N35)+(M35*O35) | Q35: =IF(P35>='🎛️ PANEL DE CONTROL'!B28, "A+", IF(P35>='🎛️ PANEL DE CONTROL'!B29, "A", IF(P35>='🎛️ PANEL DE CONTROL'!B30, "A-", IF(P35>='🎛️ PANEL DE CONTROL'!B31, "B+", IF(P35>='🎛️ PANEL DE CONTROL'!B32, "B", IF(P35>='🎛️ PANEL DE CONTROL'!B33, "B-", IF(P35>='🎛️ PANEL DE CONTROL'!B34, "C+", IF(P35>='🎛️ PANEL DE CONTROL'!B35, "C", IF(P35>='🎛️ PANEL DE CONTROL'!B36, "C-", IF(P35>='🎛️ PANEL DE CONTROL'!B37, "D", "F")))))))))) | R35: =P35-'📊 Datos Originales'!I35
