Workbook

Sheet Config_Escenarios
A1: CONFIGURACION DE ESCENARIOS - BASE DE DATOS
A3: Escenario | B3: Max_C1 | C3: Max_C2 | D3: Max_C3 | E3: Pen_DPD | F3: Pen_Util | G3: Bon_Pagos | H3: Bon_Antig | I3: P_MuyNuevo | J3: P_Nuevo | K3: P_Intermedio | L3: P_Establecido | M3: P_Maduro | N3: Descripcion
A4: Produccion | B4: 600 | C4: 150 | D4: 250 | E4: 0 | F4: 0 | G4: 0 | H4: 0 | I4: 0.3 | J4: 0.4 | K4: 0.5 | L4: 0.6 | M4: 0.7 | N4: Modelo actual sin ajustes
A5: Conservador | B5: 650 | C5: 130 | D5: 220 | E5: 75 | F5: 40 | G5: 20 | H5: 20 | I5: 0.2 | J5: 0.3 | K5: 0.45 | L5: 0.55 | M5: 0.65 | N5: Penaliza fuerte, premia poco
A6: Equilibrado | B6: 600 | C6: 150 | D6: 250 | E6: 50 | F6: 25 | G6: 30 | H6: 35 | I6: 0.3 | J6: 0.4 | K6: 0.5 | L6: 0.6 | M6: 0.7 | N6: Balance entre penalizaciones y bonificaciones
A7: Agresivo | B7: 550 | C7: 180 | D7: 270 | E7: 30 | F7: 15 | G7: 50 | H7: 50 | I7: 0.45 | J7: 0.55 | K7: 0.65 | L7: 0.75 | M7: 0.8 | N7: Bonificaciones altas, confianza en PLATAM
A8: Anti-Riesgo | B8: 700 | C8: 120 | D8: 180 | E8: 100 | F8: 60 | G8: 15 | H8: 15 | I8: 0.15 | J8: 0.25 | K8: 0.4 | L8: 0.5 | M8: 0.6 | N8: Maxima prudencia, depende de HCPN
A9: Pro-Crecimiento | B9: 550 | C9: 170 | D9: 280 | E9: 25 | F9: 10 | G9: 60 | H9: 60 | I9: 0.5 | J9: 0.6 | K9: 0.7 | L9: 0.75 | M9: 0.8 | N9: Favorece adquisicion de clientes

Sheet PANEL DE CONTROL
A1: SIMULADOR DE SCORING PLATAM V6.0
A3: ESCENARIO ACTIVO | D3: Produccion | G3: Cambia el escenario o edita valores individuales abajo
A5: MAXIMOS DE COMPONENTES | I5: KPIs EN TIEMPO REAL
A6: Componente | B6: Max Original | C6: Max Simulado | D6: % del Total | E6: Diferencia | F6: Impacto
A7: Payment Performance | B7: 600 | C7: =VLOOKUP($D$3,Config_Escenarios!$A$4:$N$9,2,FALSE()) -> 600 | D7: =C7/$C$10 -> 0.6 | E7: =C7-B7 -> 0 | F7: =IF(E7>0,"+ Peso",IF(E7<0,"- Peso","Sin cambio")) -> Sin cambio | I7: =COUNTA(Datos!A:A)-1 -> 200 | K7: =ROUND(AVERAGE(Datos!H:H),1) -> 649
A8: Payment Plan History | B8: 150 | C8: =VLOOKUP($D$3,Config_Escenarios!$A$4:$N$9,3,FALSE()) -> 150 | D8: =C8/$C$10 -> 0.15 | E8: =C8-B8 -> 0 | F8: =IF(E8>0,"+ Peso",IF(E8<0,"- Peso","Sin cambio")) -> Sin cambio
A9: Deterioration Velocity | B9: 250 | C9: =VLOOKUP($D$3,Config_Escenarios!$A$4:$N$9,4,FALSE()) -> 250 | D9: =C9/$C$10 -> 0.25 | E9: =C9-B9 -> 0 | F9: =IF(E9>0,"+ Peso",IF(E9<0,"- Peso","Sin cambio")) -> Sin cambio | I9: Total Clientes | K9: Score Base Prom
A10: TOTAL | B10: 1000 | C10: =C7+C8+C9 -> 1000 | D10: =C10/1000 -> 1 | E10: =IF(C10=1000,"OK","ERROR") -> OK
I11: =ROUND(AVERAGE(Simulacion!P:P),1) -> 640.2 | K11: =ROUND(I11-K7,1) -> -8.8
A12: PENALIZACIONES Y BONIFICACIONES
A13: Tipo | B13: Concepto | C13: Condicion | D13: Puntos | E13: Afectados | F13: % Portfolio | G13: Impacto Pts | I13: Score Sim Prom | K13: Delta Promedio
A14: PENALIZA | B14: DPD >30 dias | C14: DPD > 30 | D14: =VLOOKUP($D$3,Config_Escenarios!$A$4:$N$9,5,FALSE()) -> 0 | E14: =COUNTIF(Datos!K:K,">30") -> 77 | F14: =E14/200 -> 0.385 | G14: =-D14*E14 -> 0
A15: PENALIZA | B15: Utilizacion >80% | C15: Util > 80% | D15: =VLOOKUP($D$3,Config_Escenarios!$A$4:$N$9,6,FALSE()) -> 0 | E15: =COUNTIF(Datos!M:M,">80") -> 53 | F15: =E15/200 -> 0.265 | G15: =-D15*E15 -> 0 | I15: =COUNTIF(Simulacion!T:T,"Mejora") -> 26 | K15: =COUNTIF(Simulacion!T:T,"Empeora") -> 92
A16: BONIFICA | B16: >90% a tiempo | C16: Late < 10% | D16: =VLOOKUP($D$3,Config_Escenarios!$A$4:$N$9,7,FALSE()) -> 0 | E16: =COUNTIF(Datos!L:L,"<10") -> 72 | F16: =E16/200 -> 0.36 | G16: =D16*E16 -> 0
A17: BONIFICA | B17: Cliente >24 meses | C17: Meses > 24 | D17: =VLOOKUP($D$3,Config_Escenarios!$A$4:$N$9,8,FALSE()) -> 0 | E17: =COUNTIF(Datos!N:N,">24") -> 36 | F17: =E17/200 -> 0.18 | G17: =D17*E17 -> 0 | I17: Mejoraron | K17: Empeoraron
A18: BALANCE NETO: | B18: =G16+G17+G14+G15 -> 0 | C18: =IF(B18>0,"Favorece portfolio",IF(B18<0,"Castiga portfolio","Neutral")) -> Neutral
I19: =ROUND(STDEV(Datos!H:H),1) -> 170.9 | K19: =ROUND(STDEV(Simulacion!P:P),1) -> 179.5
A20: PESOS DEL SISTEMA HIBRIDO (PLATAM vs HCPN)
A21: Categoria | B21: Meses | C21: Peso PLATAM | D21: Peso HCPN | E21: Clientes | F21: % Portfolio | G21: Ajuste Pagos | I21: Desv Std Base | K21: Desv Std Sim
A22: Muy Nuevo | B22: < 3m | C22: =VLOOKUP($D$3,Config_Escenarios!$A$4:$N$9,9,FALSE()) -> 0.3 | D22: =1-C22 -> 0.7 | E22: =COUNTIF(Datos!O:O,"muy_nuevo") -> 32 | F22: =E22/200 -> 0.16 | G22: +/-10% segun pagos
A23: Nuevo | B23: 3-6m | C23: =VLOOKUP($D$3,Config_Escenarios!$A$4:$N$9,10,FALSE()) -> 0.4 | D23: =1-C23 -> 0.6 | E23: =COUNTIF(Datos!O:O,"nuevo") -> 52 | F23: =E23/200 -> 0.26 | G23: +/-10% segun pagos
A24: Intermedio | B24: 6-12m | C24: =VLOOKUP($D$3,Config_Escenarios!$A$4:$N$9,11,FALSE()) -> 0.5 | D24: =1-C24 -> 0.5 | E24: =COUNTIF(Datos!O:O,"intermedio") -> 51 | F24: =E24/200 -> 0.255 | G24: +/-10% segun pagos
A25: Establecido | B25: 12-24m | C25: =VLOOKUP($D$3,Config_Escenarios!$A$4:$N$9,12,FALSE()) -> 0.6 | D25: =1-C25 -> 0.4 | E25: =COUNTIF(Datos!O:O,"establecido") -> 46 | F25: =E25/200 -> 0.23 | G25: +/-10% segun pagos
A26: Maduro | B26: > 24m | C26: =VLOOKUP($D$3,Config_Escenarios!$A$4:$N$9,13,FALSE()) -> 0.7 | D26: =1-C26 -> 0.3 | E26: =COUNTIF(Datos!O:O,"maduro") -> 19 | F26: =E26/200 -> 0.095 | G26: +/-10% segun pagos
A28: UMBRALES DE RATING
A29: Rating | B29: Score Min | C29: Descripcion | D29: Clientes
A30: A+ | B30: 900 | C30: Excelente | D30: =COUNTIF(Simulacion!Q:Q,"A+") -> 24
A31: A | B31: 850 | C31: Muy Bueno | D31: =COUNTIF(Simulacion!Q:Q,"A") -> 8
A32: A- | B32: 800 | C32: Bueno Superior | D32: =COUNTIF(Simulacion!Q:Q,"A-") -> 9
A33: B+ | B33: 750 | C33: Bueno | D33: =COUNTIF(Simulacion!Q:Q,"B+") -> 13
A34: B | B34: 700 | C34: Aceptable Superior | D34: =COUNTIF(Simulacion!Q:Q,"B") -> 18
A35: B- | B35: 650 | C35: Aceptable | D35: =COUNTIF(Simulacion!Q:Q,"B-") -> 13
A36: C+ | B36: 600 | C36: Regular Superior | D36: =COUNTIF(Simulacion!Q:Q,"C+") -> 18
A37: C | B37: 550 | C37: Regular | D37: =COUNTIF(Simulacion!Q:Q,"C") -> 32
A38: C- | B38: 500 | C38: Regular Bajo | D38: =COUNTIF(Simulacion!Q:Q,"C-") -> 22
A39: D+ | B39: 450 | C39: Deficiente Superior | D39: =COUNTIF(Simulacion!Q:Q,"D+") -> 8
A40: D | B40: 400 | C40: Deficiente | D40: =COUNTIF(Simulacion!Q:Q,"D") -> 16
A41: F | B41: 0 | C41: Muy Deficiente | D41: =COUNTIF(Simulacion!Q:Q,"F") -> 19

Sheet Datos
A1: cedula | B1: score_payment_performance | C1: score_payment_plan | D1: score_deterioration | E1: platam_score | F1: platam_rating | G1: experian_score_normalized | H1: hybrid_score | I1: hybrid_rating | J1: payment_id_count | K1: days_past_due_mean | L1: pct_late | M1: pct_utilization | N1: months_as_client | O1: categoria_madurez | P1: peso_platam_usado | Q1: perfil_riesgo
A2: 84865655 | B2: 600 | C2: 150 | D2: 250 | E2: 1000 | F2: A+ | G2: 895.92 | H2: 968.78 | I2: A+ | J2: 44 | K2: -9 | L2: 1.2 | M2: 14.68 | N2: 48 | O2: maduro | P2: 0.7 | Q2: excelente
A3: 39898663 | B3: 600 | C3: 150 | D3: 250 | E3: 1000 | F3: A+ | G3: 911.75 | H3: 964.7 | I3: A+ | J3: 48 | K3: -0.9 | L3: 1.7 | M3: 15.45 | N3: 30 | O3: establecido | P3: 0.6 | Q3: excelente
A4: 60106450 | B4: 530 | C4: 150 | D4: 200 | E4: 880 | F4: A | G4: 928.52 | H4: 894.56 | I4: A | J4: 7 | K4: -28.4 | L4: 7.8 | M4: 16.98 | N4: 36 | O4: maduro | P4: 0.7 | Q4: excelente
A5: 34784923 | B5: 600 | C5: 150 | D5: 250 | E5: 1000 | F5: A+ | G5: 880.46 | H5: 964.14 | I5: A+ | J5: 24 | K5: -29.5 | L5: 7.5 | M5: 26.9 | N5: 36 | O5: maduro | P5: 0.7 | Q5: excelente
A6: 41431975 | B6: 530 | C6: 150 | D6: 250 | E6: 930 | F6: A+ | G6: 916.25 | H6: 925.88 | I6: A+ | J6: 10 | K6: -0.8 | L6: 1.4 | M6: 21.73 | N6: 36 | O6: maduro | P6: 0.7 | Q6: excelente
A7: 70333861 | B7: 530 | C7: 150 | D7: 200 | E7: 880 | F7: A | G7: 909.79 | H7: 891.92 | I7: A | J7: 12 | K7: -0.5 | L7: 3.6 | M7: 21.85 | N7: 60 | O7: establecido | P7: 0.6 | Q7: excelente
A8: 19016961 | B8: 600 | C8: 150 | D8: 250 | E8: 1000 | F8: A+ | G8: 885.68 | H8: 965.7 | I8: A+ | J8: 49 | K8: -0.4 | L8: 6 | M8: 26.19 | N8: 60 | O8: maduro | P8: 0.7 | Q8: excelente
A9: 12633705 | B9: 530 | C9: 150 | D9: 200 | E9: 880 | F9: A | G9: 851.41 | H9: 871.42 | I9: A | J9: 12 | K9: 4.5 | L9: 6.2 | M9: 15.96 | N9: 60 | O9: maduro | P9: 0.7 | Q9: excelente
A10: 99166838 | B10: 600 | C10: 150 | D10: 200 | E10: 950 | F10: A+ | G10: 894.95 | H10: 933.48 | I10: A+ | J10: 27 | K10: -17.5 | L10: 0.9 | M10: 35.89 | N10: 60 | O10: maduro | P10: 0.7 | Q10: excelente
A11: 92217102 | B11: 600 | C11: 150 | D11: 250 | E11: 1000 | F11: A+ | G11: 921.32 | H11: 968.53 | I11: A+ | J11: 30 | K11: -20.4 | L11: 4.5 | M11: 21.49 | N11: 48 | O11: establecido | P11: 0.6 | Q11: excelente
A12: 11204918 | B12: 530 | C12: 150 | D12: 200 | E12: 880 | F12: A | G12: 853.14 | H12: 869.26 | I12: A | J12: 36 | K12: -5.1 | L12: 0.9 | M12: 23.18 | N12: 48 | O12: establecido | P12: 0.6 | Q12: excelente
A13: 23938272 | B13: 600 | C13: 150 | D13: 250 | E13: 1000 | F13: A+ | G13: 878.98 | H13: 963.69 | I13: A+ | J13: 6 | K13: -11.1 | L13: 1.6 | M13: 38.29 | N13: 48 | O13: maduro | P13: 0.7 | Q13: excelente
... A201: 68748485 | B201: 100 | C201: 0 | D201: 50 | E201: 150 | F201: F | G201: 894.31 | H201: 671.02 | I201: B- | J201: 34 | K201: 47.5 | L201: 41 | M201: 71.66 | N201: 2 | O201: muy_nuevo | P201: 0.3 | Q201: outlier

Sheet Simulacion
A1: ID | B1: C1_Base | C1: C2_Base | D1: C3_Base | E1: C1_Sim | F1: C2_Sim | G1: C3_Sim | H1: Score_Comp | I1: Penaliz | J1: Bonif | K1: Score_PLATAM | L1: Score_HCPN | M1: Peso_Base | N1: Ajuste_Pago | O1: Peso_Final | P1: Score_Hibrido | Q1: Rating_Sim | R1: Rating_Orig | S1: Delta_Score | T1: Cambio | U1: Categoria | V1: Perfil
A2: =Datos!A2 -> 84865655 | B2: =Datos!B2 -> 600 | C2: =Datos!C2 -> 150 | D2: =Datos!D2 -> 250 | E2: =(B2/600)*'PANEL DE CONTROL'!$C$7 -> 600 | F2: =(C2/150)*'PANEL DE CONTROL'!$C$8 -> 150 | G2: =(D2/250)*'PANEL DE CONTROL'!$C$9 -> 250 | H2: =E2+F2+G2 -> 1000 | I2: =IF(Datos!K2>30,'PANEL DE CONTROL'!$D$14,0)+IF(Datos!M2>80,'PANEL DE CONTROL'!$D$15,0) -> 0 | J2: =IF(Datos!L2<10,'PANEL DE CONTROL'!$D$16,0)+IF(Datos!N2>24,'PANEL DE CONTROL'!$D$17,0) -> 0 | K2: =MAX(0,MIN(1000,H2-I2+J2)) -> 1000 | L2: =Datos!G2 -> 895.92 | M2: =IF(Datos!O2="muy_nuevo",'PANEL DE CONTROL'!$C$22,IF(Datos!O2="nuevo",'PANEL DE CONTROL'!$C$23,IF(Datos!O2="intermedio",'PANEL DE CONTROL'!$C$24,IF(Datos!O2="establecido",'PANEL DE CONTROL'!$C$25,'PANEL DE CONTROL'!$C$26)))) -> 0.7 | N2: =IF(Datos!J2>=20,0.1,IF(Datos!J2<5,-0.1,0)) -> 0.1 | O2: =MIN(0.8,MAX(0.2,M2+N2)) -> 0.8 | P2: =(K2*O2)+(L2*(1-O2)) -> 979.184 | Q2: =IF(P2>='PANEL DE CONTROL'!$B$30,"A+",IF(P2>='PANEL DE CONTROL'!$B$31,"A",IF(P2>='PANEL DE CONTROL'!$B$32,"A-",IF(P2>='PANEL DE CONTROL'!$B$33,"B+",IF(P2>='PANEL DE CONTROL'!$B$34,"B",IF(P2>='PANEL DE CONTROL'!$B$35,"B-",IF(P2>='PANEL DE CONTROL'!$B$36,"C+",IF(P2>='PANEL DE CONTROL'!$B$37,"C",IF(P2>='PANEL DE CONTROL'!$B$38,"C-",IF(P2>='PANEL DE CONTROL'!$B$39,"D+",IF(P2>='PANEL DE CONTROL'!$B$40,"D","F"))))))))))) -> A+ | R2: =Datos!I2 -> A+ | S2: =P2-Datos!H2 -> 10.404 | T2: =IF(ABS(S2)<5,"Igual",IF(S2>0,"Mejora","Empeora")) -> Mejora | U2: =Datos!O2 -> maduro | V2: =Datos!Q2 -> excelente
A3: =Datos!A3 -> 39898663 | B3: =Datos!B3 -> 600 | C3: =Datos!C3 -> 150 | D3: =Datos!D3 -> 250 | E3: =(B3/600)*'PANEL DE CONTROL'!$C$7 -> 600 | F3: =(C3/150)*'PANEL DE CONTROL'!$C$8 -> 150 | G3: =(D3/250)*'PANEL DE CONTROL'!$C$9 -> 250 | H3: =E3+F3+G3 -> 1000 | I3: =IF(Datos!K3>30,'PANEL DE CONTROL'!$D$14,0)+IF(Datos!M3>80,'PANEL DE CONTROL'!$D$15,0) -> 0 | J3: =IF(Datos!L3<10,'PANEL DE CONTROL'!$D$16,0)+IF(Datos!N3>24,'PANEL DE CONTROL'!$D$17,0) -> 0 | K3: =MAX(0,MIN(1000,H3-I3+J3)) -> 1000 | L3: =Datos!G3 -> 911.75 | M3: =IF(Datos!O3="muy_nuevo",'PANEL DE CONTROL'!$C$22,IF(Datos!O3="nuevo",'PANEL DE CONTROL'!$C$23,IF(Datos!O3="intermedio",'PANEL DE CONTROL'!$C$24,IF(Datos!O3="establecido",'PANEL DE CONTROL'!$C$25,'PANEL DE CONTROL'!$C$26)))) -> 0.6 | N3: =IF(Datos!J3>=20,0.1,IF(Datos!J3<5,-0.1,0)) -> 0.1 | O3: =MIN(0.8,MAX(0.2,M3+N3)) -> 0.7 | P3: =(K3*O3)+(L3*(1-O3)) -> 973.525 | Q3: =IF(P3>='PANEL DE CONTROL'!$B$30,"A+",IF(P3>='PANEL DE CONTROL'!$B$31,"A",IF(P3>='PANEL DE CONTROL'!$B$32,"A-",IF(P3>='PANEL DE CONTROL'!$B$33,"B+",IF(P3>='PANEL DE CONTROL'!$B$34,"B",IF(P3>='PANEL DE CONTROL'!$B$35,"B-",IF(P3>='PANEL DE CONTROL'!$B$36,"C+",IF(P3>='PANEL DE CONTROL'!$B$37,"C",IF(P3>='PANEL DE CONTROL'!$B$38,"C-",IF(P3>='PANEL DE CONTROL'!$B$39,"D+",IF(P3>='PANEL DE CONTROL'!$B$40,"D","F"))))))))))) -> A+ | R3: =Datos!I3 -> A+ | S3: =P3-Datos!H3 -> 8.825 | T3: =IF(ABS(S3)<5,"Igual",IF(S3>0,"Mejora","Empeora")) -> Mejora | U3: =Datos!O3 -> establecido | V3: =Datos!Q3 -> excelente
A4: =Datos!A4 -> 60106450 | B4: =Datos!B4 -> 530 | C4: =Datos!C4 -> 150 | D4: =Datos!D4 -> 200 | E4: =(B4/600)*'PANEL DE CONTROL'!$C$7 -> 530 | F4: =(C4/150)*'PANEL DE CONTROL'!$C$8 -> 150 | G4: =(D4/250)*'PANEL DE CONTROL'!$C$9 -> 200 | H4: =E4+F4+G4 -> 880 | I4: =IF(Datos!K4>30,'PANEL DE CONTROL'!$D$14,0)+IF(Datos!M4>80,'PANEL DE CONTROL'!$D$15,0) -> 0 | J4: =IF(Datos!L4<10,'PANEL DE CONTROL'!$D$16,0)+IF(Datos!N4>24,'PANEL DE CONTROL'!$D$17,0) -> 0 | K4: =MAX(0,MIN(1000,H4-I4+J4)) -> 880 | L4: =Datos!G4 -> 928.52 | M4: =IF(Datos!O4="muy_nuevo",'PANEL DE CONTROL'!$C$22,IF(Datos!O4="nuevo",'PANEL DE CONTROL'!$C$23,IF(Datos!O4="intermedio",'PANEL DE CONTROL'!$C$24,IF(Datos!O4="establecido",'PANEL DE CONTROL'!$C$25,'PANEL DE CONTROL'!$C$26)))) -> 0.7 | N4: =IF(Datos!J4>=20,0.1,IF(Datos!J4<5,-0.1,0)) -> 0 | O4: =MIN(0.8,MAX(0.2,M4+N4)) -> 0.7 | P4: =(K4*O4)+(L4*(1-O4)) -> 894.556 | Q4: =IF(P4>='PANEL DE CONTROL'!$B$30,"A+",IF(P4>='PANEL DE CONTROL'!$B$31,"A",IF(P4>='PANEL DE CONTROL'!$B$32,"A-",IF(P4>='PANEL DE CONTROL'!$B$33,"B+",IF(P4>='PANEL DE CONTROL'!$B$34,"B",IF(P4>='PANEL DE CONTROL'!$B$35,"B-",IF(P4>='PANEL DE CONTROL'!$B$36,"C+",IF(P4>='PANEL DE CONTROL'!$B$37,"C",IF(P4>='PANEL DE CONTROL'!$B$38,"C-",IF(P4>='PANEL DE CONTROL'!$B$39,"D+",IF(P4>='PANEL DE CONTROL'!$B$40,"D","F"))))))))))) -> A | R4: =Datos!I4 -> A | S4: =P4-Datos!H4 -> -0.004 | T4: =IF(ABS(S4)<5,"Igual",IF(S4>0,"Mejora","Empeora")) -> Igual | U4: =Datos!O4 -> maduro | V4: =Datos!Q4 -> excelente
A5: =Datos!A5 -> 34784923 | B5: =Datos!B5 -> 600 | C5: =Datos!C5 -> 150 | D5: =Datos!D5 -> 250 | E5: =(B5/600)*'PANEL DE CONTROL'!$C$7 -> 600 | F5: =(C5/150)*'PANEL DE CONTROL'!$C$8 -> 150 | G5: =(D5/250)*'PANEL DE CONTROL'!$C$9 -> 250 | H5: =E5+F5+G5 -> 1000 | I5: =IF(Datos!K5>30,'PANEL DE CONTROL'!$D$14,0)+IF(Datos!M5>80,'PANEL DE CONTROL'!$D$15,0) -> 0 | J5: =IF(Datos!L5<10,'PANEL DE CONTROL'!$D$16,0)+IF(Datos!N5>24,'PANEL DE CONTROL'!$D$17,0) -> 0 | K5: =MAX(0,MIN(1000,H5-I5+J5)) -> 1000 | L5: =Datos!G5 -> 880.46 | M5: =IF(Datos!O5="muy_nuevo",'PANEL DE CONTROL'!$C$22,IF(Datos!O5="nuevo",'PANEL DE CONTROL'!$C$23,IF(Datos!O5="intermedio",'PANEL DE CONTROL'!$C$24,IF(Datos!O5="establecido",'PANEL DE CONTROL'!$C$25,'PANEL DE CONTROL'!$C$26)))) -> 0.7 | N5: =IF(Datos!J5>=20,0.1,IF(Datos!J5<5,-0.1,0)) -> 0.1 | O5: =MIN(0.8,MAX(0.2,M5+N5)) -> 0.8 | P5: =(K5*O5)+(L5*(1-O5)) -> 976.092 | Q5: =IF(P5>='PANEL DE CONTROL'!$B$30,"A+",IF(P5>='PANEL DE CONTROL'!$B$31,"A",IF(P5>='PANEL DE CONTROL'!$B$32,"A-",IF(P5>='PANEL DE CONTROL'!$B$33,"B+",IF(P5>='PANEL DE CONTROL'!$B$34,"B",IF(P5>='PANEL DE CONTROL'!$B$35,"B-",IF(P5>='PANEL DE CONTROL'!$B$36,"C+",IF(P5>='PANEL DE CONTROL'!$B$37,"C",IF(P5>='PANEL DE CONTROL'!$B$38,"C-",IF(P5>='PANEL DE CONTROL'!$B$39,"D+",IF(P5>='PANEL DE CONTROL'!$B$40,"D","F"))))))))))) -> A+ | R5: =Datos!I5 -> A+ | S5: =P5-Datos!H5 -> 11.952 | T5: =IF(ABS(S5)<5,"Igual",IF(S5>0,"Mejora","Empeora")) -> Mejora | U5: =Datos!O5 -> maduro | V5: =Datos!Q5 -> excelente
A6: =Datos!A6 -> 41431975 | B6: =Datos!B6 -> 530 | C6: =Datos!C6 -> 150 | D6: =Datos!D6 -> 250 | E6: =(B6/600)*'PANEL DE CONTROL'!$C$7 -> 530 | F6: =(C6/150)*'PANEL DE CONTROL'!$C$8 -> 150 | G6: =(D6/250)*'PANEL DE CONTROL'!$C$9 -> 250 | H6: =E6+F6+G6 -> 930 | I6: =IF(Datos!K6>30,'PANEL DE CONTROL'!$D$14,0)+IF(Datos!M6>80,'PANEL DE CONTROL'!$D$15,0) -> 0 | J6: =IF(Datos!L6<10,'PANEL DE CONTROL'!$D$16,0)+IF(Datos!N6>24,'PANEL DE CONTROL'!$D$17,0) -> 0 | K6: =MAX(0,MIN(1000,H6-I6+J6)) -> 930 | L6: =Datos!G6 -> 916.25 | M6: =IF(Datos!O6="muy_nuevo",'PANEL DE CONTROL'!$C$22,IF(Datos!O6="nuevo",'PANEL DE CONTROL'!$C$23,IF(Datos!O6="intermedio",'PANEL DE CONTROL'!$C$24,IF(Datos!O6="establecido",'PANEL DE CONTROL'!$C$25,'PANEL DE CONTROL'!$C$26)))) -> 0.7 | N6: =IF(Datos!J6>=20,0.1,IF(Datos!J6<5,-0.1,0)) -> 0 | O6: =MIN(0.8,MAX(0.2,M6+N6)) -> 0.7 | P6: =(K6*O6)+(L6*(1-O6)) -> 925.875 | Q6: =IF(P6>='PANEL DE CONTROL'!$B$30,"A+",IF(P6>='PANEL DE CONTROL'!$B$31,"A",IF(P6>='PANEL DE CONTROL'!$B$32,"A-",IF(P6>='PANEL DE CONTROL'!$B$33,"B+",IF(P6>='PANEL DE CONTROL'!$B$34,"B",IF(P6>='PANEL DE CONTROL'!$B$35,"B-",IF(P6>='PANEL DE CONTROL'!$B$36,"C+",IF(P6>='PANEL DE CONTROL'!$B$37,"C",IF(P6>='PANEL DE CONTROL'!$B$38,"C-",IF(P6>='PANEL DE CONTROL'!$B$39,"D+",IF(P6>='PANEL DE CONTROL'!$B$40,"D","F"))))))))))) -> A+ | R6: =Datos!I6 -> A+ | S6: =P6-Datos!H6 -> -0.005 | T6: =IF(ABS(S6)<5,"Igual",IF(S6>0,"Mejora","Empeora")) -> Igual | U6: =Datos!O6 -> maduro | V6: =Datos!Q6 -> excelente
A7: =Datos!A7 -> 70333861 | B7: =Datos!B7 -> 530 | C7: =Datos!C7 -> 150 | D7: =Datos!D7 -> 200 | E7: =(B7/600)*'PANEL DE CONTROL'!$C$7 -> 530 | F7: =(C7/150)*'PANEL DE CONTROL'!$C$8 -> 150 | G7: =(D7/250)*'PANEL DE CONTROL'!$C$9 -> 200 | H7: =E7+F7+G7 -> 880 | I7: =IF(Datos!K7>30,'PANEL DE CONTROL'!$D$14,0)+IF(Datos!M7>80,'PANEL DE CONTROL'!$D$15,0) -> 0 | J7: =IF(Datos!L7<10,'PANEL DE CONTROL'!$D$16,0)+IF(Datos!N7>24,'PANEL DE CONTROL'!$D$17,0) -> 0 | K7: =MAX(0,MIN(1000,H7-I7+J7)) -> 880 | L7: =Datos!G7 -> 909.79 | M7: =IF(Datos!O7="muy_nuevo",'PANEL DE CONTROL'!$C$22,IF(Datos!O7="nuevo",'PANEL DE CONTROL'!$C$23,IF(Datos!O7="intermedio",'PANEL DE CONTROL'!$C$24,IF(Datos!O7="establecido",'PANEL DE CONTROL'!$C$25,'PANEL DE CONTROL'!$C$26)))) -> 0.6 | N7: =IF(Datos!J7>=20,0.1,IF(Datos!J7<5,-0.1,0)) -> 0 | O7: =MIN(0.8,MAX(0.2,M7+N7)) -> 0.6 | P7: =(K7*O7)+(L7*(1-O7)) -> 891.916 | Q7: =IF(P7>='PANEL DE CONTROL'!$B$30,"A+",IF(P7>='PANEL DE CONTROL'!$B$31,"A",IF(P7>='PANEL DE CONTROL'!$B$32,"A-",IF(P7>='PANEL DE CONTROL'!$B$33,"B+",IF(P7>='PANEL DE CONTROL'!$B$34,"B",IF(P7>='PANEL DE CONTROL'!$B$35,"B-",IF(P7>='PANEL DE CONTROL'!$B$36,"C+",IF(P7>='PANEL DE CONTROL'!$B$37,"C",IF(P7>='PANEL DE CONTROL'!$B$38,"C-",IF(P7>='PANEL DE CONTROL'!$B$39,"D+",IF(P7>='PANEL DE CONTROL'!$B$40,"D","F"))))))))))) -> A | R7: =Datos!I7 -> A | S7: =P7-Datos!H7 -> -0.004 | T7: =IF(ABS(S7)<5,"Igual",IF(S7>0,"Mejora","Empeora")) -> Igual | U7: =Datos!O7 -> establecido | V7: =Datos!Q7 -> excelente
A8: =Datos!A8 -> 19016961 | B8: =Datos!B8 -> 600 | C8: =Datos!C8 -> 150 | D8: =Datos!D8 -> 250 | E8: =(B8/600)*'PANEL DE CONTROL'!$C$7 -> 600 | F8: =(C8/150)*'PANEL DE CONTROL'!$C$8 -> 150 | G8: =(D8/250)*'PANEL DE CONTROL'!$C$9 -> 250 | H8: =E8+F8+G8 -> 1000 | I8: =IF(Datos!K8>30,'PANEL DE CONTROL'!$D$14,0)+IF(Datos!M8>80,'PANEL DE CONTROL'!$D$15,0) -> 0 | J8: =IF(Datos!L8<10,'PANEL DE CONTROL'!$D$16,0)+IF(Datos!N8>24,'PANEL DE CONTROL'!$D$17,0) -> 0 | K8: =MAX(0,MIN(1000,H8-I8+J8)) -> 1000 | L8: =Datos!G8 -> 885.68 | M8: =IF(Datos!O8="muy_nuevo",'PANEL DE CONTROL'!$C$22,IF(Datos!O8="nuevo",'PANEL DE CONTROL'!$C$23,IF(Datos!O8="intermedio",'PANEL DE CONTROL'!$C$24,IF(Datos!O8="establecido",'PANEL DE CONTROL'!$C$25,'PANEL DE CONTROL'!$C$26)))) -> 0.7 | N8: =IF(Datos!J8>=20,0.1,IF(Datos!J8<5,-0.1,0)) -> 0.1 | O8: =MIN(0.8,MAX(0.2,M8+N8)) -> 0.8 | P8: =(K8*O8)+(L8*(1-O8)) -> 977.136 | Q8: =IF(P8>='PANEL DE CONTROL'!$B$30,"A+",IF(P8>='PANEL DE CONTROL'!$B$31,"A",IF(P8>='PANEL DE CONTROL'!$B$32,"A-",IF(P8>='PANEL DE CONTROL'!$B$33,"B+",IF(P8>='PANEL DE CONTROL'!$B$34,"B",IF(P8>='PANEL DE CONTROL'!$B$35,"B-",IF(P8>='PANEL DE CONTROL'!$B$36,"C+",IF(P8>='PANEL DE CONTROL'!$B$37,"C",IF(P8>='PANEL DE CONTROL'!$B$38,"C-",IF(P8>='PANEL DE CONTROL'!$B$39,"D+",IF(P8>='PANEL DE CONTROL'!$B$40,"D","F"))))))))))) -> A+ | R8: =Datos!I8 -> A+ | S8: =P8-Datos!H8 -> 11.436 | T8: =IF(ABS(S8)<5,"Igual",IF(S8>0,"Mejora","Empeora")) -> Mejora | U8: =Datos!O8 -> maduro | V8: =Datos!Q8 -> excelente
A9: =Datos!A9 -> 12633705 | B9: =Datos!B9 -> 530 | C9: =Datos!C9 -> 150 | D9: =Datos!D9 -> 200 | E9: =(B9/600)*'PANEL DE CONTROL'!$C$7 -> 530 | F9: =(C9/150)*'PANEL DE CONTROL'!$C$8 -> 150 | G9: =(D9/250)*'PANEL DE CONTROL'!$C$9 -> 200 | H9: =E9+F9+G9 -> 880 | I9: =IF(Datos!K9>30,'PANEL DE CONTROL'!$D$14,0)+IF(Datos!M9>80,'PANEL DE CONTROL'!$D$15,0) -> 0 | J9: =IF(Datos!L9<10,'PANEL DE CONTROL'!$D$16,0)+IF(Datos!N9>24,'PANEL DE CONTROL'!$D$17,0) -> 0 | K9: =MAX(0,MIN(1000,H9-I9+J9)) -> 880 | L9: =Datos!G9 -> 851.41 | M9: =IF(Datos!O9="muy_nuevo",'PANEL DE CONTROL'!$C$22,IF(Datos!O9="nuevo",'PANEL DE CONTROL'!$C$23,IF(Datos!O9="intermedio",'PANEL DE CONTROL'!$C$24,IF(Datos!O9="establecido",'PANEL DE CONTROL'!$C$25,'PANEL DE CONTROL'!$C$26)))) -> 0.7 | N9: =IF(Datos!J9>=20,0.1,IF(Datos!J9<5,-0.1,0)) -> 0 | O9: =MIN(0.8,MAX(0.2,M9+N9)) -> 0.7 | P9: =(K9*O9)+(L9*(1-O9)) -> 871.423 | Q9: =IF(P9>='PANEL DE CONTROL'!$B$30,"A+",IF(P9>='PANEL DE CONTROL'!$B$31,"A",IF(P9>='PANEL DE CONTROL'!$B$32,"A-",IF(P9>='PANEL DE CONTROL'!$B$33,"B+",IF(P9>='PANEL DE CONTROL'!$B$34,"B",IF(P9>='PANEL DE CONTROL'!$B$35,"B-",IF(P9>='PANEL DE CONTROL'!$B$36,"C+",IF(P9>='PANEL DE CONTROL'!$B$37,"C",IF(P9>='PANEL DE CONTROL'!$B$38,"C-",IF(P9>='PANEL DE CONTROL'!$B$39,"D+",IF(P9>='PANEL DE CONTROL'!$B$40,"D","F"))))))))))) -> A | R9: =Datos!I9 -> A | S9: =P9-Datos!H9 -> 0.003 | T9: =IF(ABS(S9)<5,"Igual",IF(S9>0,"Mejora","Empeora")) -> Igual | U9: =Datos!O9 -> maduro | V9: =Datos!Q9 -> excelente
A10: =Datos!A10 -> 99166838 | B10: =Datos!B10 -> 600 | C10: =Datos!C10 -> 150 | D10: =Datos!D10 -> 200 | E10: =(B10/600)*'PANEL DE CONTROL'!$C$7 -> 600 | F10: =(C10/150)*'PANEL DE CONTROL'!$C$8 -> 150 | G10: =(D10/250)*'PANEL DE CONTROL'!$C$9 -> 200 | H10: =E10+F10+G10 -> 950 | I10: =IF(Datos!K10>30,'PANEL DE CONTROL'!$D$14,0)+IF(Datos!M10>80,'PANEL DE CONTROL'!$D$15,0) -> 0 | J10: =IF(Datos!L10<10,'PANEL DE CONTROL'!$D$16,0)+IF(Datos!N10>24,'PANEL DE CONTROL'!$D$17,0) -> 0 | K10: =MAX(0,MIN(1000,H10-I10+J10)) -> 950 | L10: =Datos!G10 -> 894.95 | M10: =IF(Datos!O10="muy_nuevo",'PANEL DE CONTROL'!$C$22,IF(Datos!O10="nuevo",'PANEL DE CONTROL'!$C$23,IF(Datos!O10="intermedio",'PANEL DE CONTROL'!$C$24,IF(Datos!O10="establecido",'PANEL DE CONTROL'!$C$25,'PANEL DE CONTROL'!$C$26)))) -> 0.7 | N10: =IF(Datos!J10>=20,0.1,IF(Datos!J10<5,-0.1,0)) -> 0.1 | O10: =MIN(0.8,MAX(0.2,M10+N10)) -> 0.8 | P10: =(K10*O10)+(L10*(1-O10)) -> 938.99 | Q10: =IF(P10>='PANEL DE CONTROL'!$B$30,"A+",IF(P10>='PANEL DE CONTROL'!$B$31,"A",IF(P10>='PANEL DE CONTROL'!$B$32,"A-",IF(P10>='PANEL DE CONTROL'!$B$33,"B+",IF(P10>='PANEL DE CONTROL'!$B$34,"B",IF(P10>='PANEL DE CONTROL'!$B$35,"B-",IF(P10>='PANEL DE CONTROL'!$B$36,"C+",IF(P10>='PANEL DE CONTROL'!$B$37,"C",IF(P10>='PANEL DE CONTROL'!$B$38,"C-",IF(P10>='PANEL DE CONTROL'!$B$39,"D+",IF(P10>='PANEL DE CONTROL'!$B$40,"D","F"))))))))))) -> A+ | R10: =Datos!I10 -> A+ | S10: =P10-Datos!H10 -> 5.51 | T10: =IF(ABS(S10)<5,"Igual",IF(S10>0,"Mejora","Empeora")) -> Mejora | U10: =Datos!O10 -> maduro | V10: =Datos!Q10 -> excelente
A11: =Datos!A11 -> 92217102 | B11: =Datos!B11 -> 600 | C11: =Datos!C11 -> 150 | D11: =Datos!D11 -> 250 | E11: =(B11/600)*'PANEL DE CONTROL'!$C$7 -> 600 | F11: =(C11/150)*'PANEL DE CONTROL'!$C$8 -> 150 | G11: =(D11/250)*'PANEL DE CONTROL'!$C$9 -> 250 | H11: =E11+F11+G11 -> 1000 | I11: =IF(Datos!K11>30,'PANEL DE CONTROL'!$D$14,0)+IF(Datos!M11>80,'PANEL DE CONTROL'!$D$15,0) -> 0 | J11: =IF(Datos!L11<10,'PANEL DE CONTROL'!$D$16,0)+IF(Datos!N11>24,'PANEL DE CONTROL'!$D$17,0) -> 0 | K11: =MAX(0,MIN(1000,H11-I11+J11)) -> 1000 | L11: =Datos!G11 -> 921.32 | M11: =IF(Datos!O11="muy_nuevo",'PANEL DE CONTROL'!$C$22,IF(Datos!O11="nuevo",'PANEL DE CONTROL'!$C$23,IF(Datos!O11="intermedio",'PANEL DE CONTROL'!$C$24,IF(Datos!O11="establecido",'PANEL DE CONTROL'!$C$25,'PANEL DE CONTROL'!$C$26)))) -> 0.6 | N11: =IF(Datos!J11>=20,0.1,IF(Datos!J11<5,-0.1,0)) -> 0.1 | O11: =MIN(0.8,MAX(0.2,M11+N11)) -> 0.7 | P11: =(K11*O11)+(L11*(1-O11)) -> 976.396 | Q11: =IF(P11>='PANEL DE CONTROL'!$B$30,"A+",IF(P11>='PANEL DE CONTROL'!$B$31,"A",IF(P11>='PANEL DE CONTROL'!$B$32,"A-",IF(P11>='PANEL DE CONTROL'!$B$33,"B+",IF(P11>='PANEL DE CONTROL'!$B$34,"B",IF(P11>='PANEL DE CONTROL'!$B$35,"B-",IF(P11>='PANEL DE CONTROL'!$B$36,"C+",IF(P11>='PANEL DE CONTROL'!$B$37,"C",IF(P11>='PANEL DE CONTROL'!$B$38,"C-",IF(P11>='PANEL DE CONTROL'!$B$39,"D+",IF(P11>='PANEL DE CONTROL'!$B$40,"D","F"))))))))))) -> A+ | R11: =Datos!I11 -> A+ | S11: =P11-Datos!H11 -> 7.866 | T11: =IF(ABS(S11)<5,"Igual",IF(S11>0,"Mejora","Empeora")) -> Mejora | U11: =Datos!O11 -> establecido | V11: =Datos!Q11 -> excelente
A12: =Datos!A12 -> 11204918 | B12: =Datos!B12 -> 530 | C12: =Datos!C12 -> 150 | D12: =Datos!D12 -> 200 | E12: =(B12/600)*'PANEL DE CONTROL'!$C$7 -> 530 | F12: =(C12/150)*'PANEL DE CONTROL'!$C$8 -> 150 | G12: =(D12/250)*'PANEL DE CONTROL'!$C$9 -> 200 | H12: =E12+F12+G12 -> 880 | I12: =IF(Datos!K12>30,'PANEL DE CONTROL'!$D$14,0)+IF(Datos!M12>80,'PANEL DE CONTROL'!$D$15,0) -> 0 | J12: =IF(Datos!L12<10,'PANEL DE CONTROL'!$D$16,0)+IF(Datos!N12>24,'PANEL DE CONTROL'!$D$17,0) -> 0 | K12: =MAX(0,MIN(1000,H12-I12+J12)) -> 880 | L12: =Datos!G12 -> 853.14 | M12: =IF(Datos!O12="muy_nuevo",'PANEL DE CONTROL'!$C$22,IF(Datos!O12="nuevo",'PANEL DE CONTROL'!$C$23,IF(Datos!O12="intermedio",'PANEL DE CONTROL'!$C$24,IF(Datos!O12="establecido",'PANEL DE CONTROL'!$C$25,'PANEL DE CONTROL'!$C$26)))) -> 0.6 | N12: =IF(Datos!J12>=20,0.1,IF(Datos!J12<5,-0.1,0)) -> 0.1 | O12: =MIN(0.8,MAX(0.2,M12+N12)) -> 0.7 | P12: =(K12*O12)+(L12*(1-O12)) -> 871.942 | Q12: =IF(P12>='PANEL DE CONTROL'!$B$30,"A+",IF(P12>='PANEL DE CONTROL'!$B$31,"A",IF(P12>='PANEL DE CONTROL'!$B$32,"A-",IF(P12>='PANEL DE CONTROL'!$B$33,"B+",IF(P12>='PANEL DE CONTROL'!$B$34,"B",IF(P12>='PANEL DE CONTROL'!$B$35,"B-",IF(P12>='PANEL DE CONTROL'!$B$36,"C+",IF(P12>='PANEL DE CONTROL'!$B$37,"C",IF(P12>='PANEL DE CONTROL'!$B$38,"C-",IF(P12>='PANEL DE CONTROL'!$B$39,"D+",IF(P12>='PANEL DE CONTROL'!$B$40,"D","F"))))))))))) -> A | R12: =Datos!I12 -> A | S12: =P12-Datos!H12 -> 2.682 | T12: =IF(ABS(S12)<5,"Igual",IF(S12>0,"Mejora","Empeora")) -> Igual | U12: =Datos!O12 -> establecido | V12: =Datos!Q12 -> excelente
A13: =Datos!A13 -> 23938272 | B13: =Datos!B13 -> 600 | C13: =Datos!C13 -> 150 | D13: =Datos!D13 -> 250 | E13: =(B13/600)*'PANEL DE CONTROL'!$C$7 -> 600 | F13: =(C13/150)*'PANEL DE CONTROL'!$C$8 -> 150 | G13: =(D13/250)*'PANEL DE CONTROL'!$C$9 -> 250 | H13: =E13+F13+G13 -> 1000 | I13: =IF(Datos!K13>30,'PANEL DE CONTROL'!$D$14,0)+IF(Datos!M13>80,'PANEL DE CONTROL'!$D$15,0) -> 0 | J13: =IF(Datos!L13<10,'PANEL DE CONTROL'!$D$16,0)+IF(Datos!N13>24,'PANEL DE CONTROL'!$D$17,0) -> 0 | K13: =MAX(0,MIN(1000,H13-I13+J13)) -> 1000 | L13: =Datos!G13 -> 878.98 | M13: =IF(Datos!O13="muy_nuevo",'PANEL DE CONTROL'!$C$22,IF(Datos!O13="nuevo",'PANEL DE CONTROL'!$C$23,IF(Datos!O13="intermedio",'PANEL DE CONTROL'!$C$24,IF(Datos!O13="establecido",'PANEL DE CONTROL'!$C$25,'PANEL DE CONTROL'!$C$26)))) -> 0.7 | N13: =IF(Datos!J13>=20,0.1,IF(Datos!J13<5,-0.1,0)) -> 0 | O13: =MIN(0.8,MAX(0.2,M13+N13)) -> 0.7 | P13: =(K13*O13)+(L13*(1-O13)) -> 963.694 | Q13: =IF(P13>='PANEL DE CONTROL'!$B$30,"A+",IF(P13>='PANEL DE CONTROL'!$B$31,"A",IF(P13>='PANEL DE CONTROL'!$B$32,"A-",IF(P13>='PANEL DE CONTROL'!$B$33,"B+",IF(P13>='PANEL DE CONTROL'!$B$34,"B",IF(P13>='PANEL DE CONTROL'!$B$35,"B-",IF(P13>='PANEL DE CONTROL'!$B$36,"C+",IF(P13>='PANEL DE CONTROL'!$B$37,"C",IF(P13>='PANEL DE CONTROL'!$B$38,"C-",IF(P13>='PANEL DE CONTROL'!$B$39,"D+",IF(P13>='PANEL DE CONTROL'!$B$40,"D","F"))))))))))) -> A+ | R13: =Datos!I13 -> A+ | S13: =P13-Datos!H13 -> 0.004 | T13: =IF(ABS(S13)<5,"Igual",IF(S13>0,"Mejora","Empeora")) -> Igual | U13: =Datos!O13 -> maduro | V13: =Datos!Q13 -> excelente
... A201: =Datos!A201 -> 68748485 | B201: =Datos!B201 -> 100 | C201: =Datos!C201 -> 0 | D201: =Datos!D201 -> 50 | E201: =(B201/600)*'PANEL DE CONTROL'!$C$7 -> 100 | F201: =(C201/150)*'PANEL DE CONTROL'!$C$8 -> 0 | G201: =(D201/250)*'PANEL DE CONTROL'!$C$9 -> 50 | H201: =E201+F201+G201 -> 150 | I201: =IF(Datos!K201>30,'PANEL DE CONTROL'!$D$14,0)+IF(Datos!M201>80,'PANEL DE CONTROL'!$D$15,0) -> 0 | J201: =IF(Datos!L201<10,'PANEL DE CONTROL'!$D$16,0)+IF(Datos!N201>24,'PANEL DE CONTROL'!$D$17,0) -> 0 | K201: =MAX(0,MIN(1000,H201-I201+J201)) -> 150 | L201: =Datos!G201 -> 894.31 | M201: =IF(Datos!O201="muy_nuevo",'PANEL DE CONTROL'!$C$22,IF(Datos!O201="nuevo",'PANEL DE CONTROL'!$C$23,IF(Datos!O201="intermedio",'PANEL DE CONTROL'!$C$24,IF(Datos!O201="establecido",'PANEL DE CONTROL'!$C$25,'PANEL DE CONTROL'!$C$26)))) -> 0.3 | N201: =IF(Datos!J201>=20,0.1,IF(Datos!J201<5,-0.1,0)) -> 0.1 | O201: =MIN(0.8,MAX(0.2,M201+N201)) -> 0.4 | P201: =(K201*O201)+(L201*(1-O201)) -> 596.586 | Q201: =IF(P201>='PANEL DE CONTROL'!$B$30,"A+",IF(P201>='PANEL DE CONTROL'!$B$31,"A",IF(P201>='PANEL DE CONTROL'!$B$32,"A-",IF(P201>='PANEL DE CONTROL'!$B$33,"B+",IF(P201>='PANEL DE CONTROL'!$B$34,"B",IF(P201>='PANEL DE CONTROL'!$B$35,"B-",IF(P201>='PANEL DE CONTROL'!$B$36,"C+",IF(P201>='PANEL DE CONTROL'!$B$37,"C",IF(P201>='PANEL DE CONTROL'!$B$38,"C-",IF(P201>='PANEL DE CONTROL'!$B$39,"D+",IF(P201>='PANEL DE CONTROL'!$B$40,"D","F"))))))))))) -> C | R201: =Datos!I201 -> B- | S201: =P201-Datos!H201 -> -74.434 | T201: =IF(ABS(S201)<5,"Igual",IF(S201>0,"Mejora","Empeora")) -> Empeora | U201: =Datos!O201 -> muy_nuevo | V201: =Datos!Q201 -> outlier

Sheet Dashboard
A1: DASHBOARD DE ANALISIS - SIMULADOR SCORING PLATAM V6.0
A3: ESCENARIO: | D3: ='PANEL DE CONTROL'!D3 -> Produccion | G3: (Cambiar en Panel de Control)
A5: =ROUND(AVERAGE(Datos!H:H),1) -> 649 | D5: =ROUND(AVERAGE(Simulacion!P:P),1) -> 640.2 | G5: =ROUND(D5-A5,1) -> -8.8 | I5: =COUNTIF(Simulacion!T:T,"Mejora") -> 26 | K5: =COUNTIF(Simulacion!T:T,"Empeora") -> 92 | M5: =COUNTIF(Simulacion!T:T,"Igual") -> 82 | O5: =ROUND(STDEV(Datos!H:H),1) -> 170.9 | Q5: =ROUND(STDEV(Simulacion!P:P),1) -> 179.5
A7: Score Promedio BASE | D7: Score Promedio SIMULADO | G7: Delta Prom | I7: Mejoraron | K7: Empeoraron | M7: Sin Cambio | O7: Desv Std Base | Q7: Desv Std Sim
A9: DISTRIBUCION DE RATINGS | I9: HCPN | J9: PLATAM_Sim | K9: Gap | L9: Perfil
A10: Rating | B10: Original | C10: Simulado | D10: Cambio | E10: Mejoraron | F10: Empeoraron | G10: Neto | I10: =Simulacion!L2 -> 895.92 | J10: =Simulacion!K2 -> 1000 | K10: =J10-I10 -> 104.08 | L10: =Simulacion!V2 -> excelente
A11: A+ | B11: =COUNTIF(Datos!I:I,"A+") -> 25 | C11: =COUNTIF(Simulacion!Q:Q,"A+") -> 24 | D11: =C11-B11 -> -1 | E11: =COUNTIFS(Simulacion!Q:Q,"A+",Simulacion!T:T,"Mejora") -> 14 | F11: =COUNTIFS(Simulacion!Q:Q,"A+",Simulacion!T:T,"Empeora") -> 0 | G11: =E11-F11 -> 14 | I11: =Simulacion!L3 -> 911.75 | J11: =Simulacion!K3 -> 1000 | K11: =J11-I11 -> 88.25 | L11: =Simulacion!V3 -> excelente
A12: A | B12: =COUNTIF(Datos!I:I,"A") -> 6 | C12: =COUNTIF(Simulacion!Q:Q,"A") -> 8 | D12: =C12-B12 -> 2 | E12: =COUNTIFS(Simulacion!Q:Q,"A",Simulacion!T:T,"Mejora") -> 1 | F12: =COUNTIFS(Simulacion!Q:Q,"A",Simulacion!T:T,"Empeora") -> 1 | G12: =E12-F12 -> 0 | I12: =Simulacion!L4 -> 928.52 | J12: =Simulacion!K4 -> 880 | K12: =J12-I12 -> -48.52 | L12: =Simulacion!V4 -> excelente
A13: A- | B13: =COUNTIF(Datos!I:I,"A-") -> 10 | C13: =COUNTIF(Simulacion!Q:Q,"A-") -> 9 | D13: =C13-B13 -> -1 | E13: =COUNTIFS(Simulacion!Q:Q,"A-",Simulacion!T:T,"Mejora") -> 0 | F13: =COUNTIFS(Simulacion!Q:Q,"A-",Simulacion!T:T,"Empeora") -> 0 | G13: =E13-F13 -> 0 | I13: =Simulacion!L5 -> 880.46 | J13: =Simulacion!K5 -> 1000 | K13: =J13-I13 -> 119.54 | L13: =Simulacion!V5 -> excelente
A14: B+ | B14: =COUNTIF(Datos!I:I,"B+") -> 14 | C14: =COUNTIF(Simulacion!Q:Q,"B+") -> 13 | D14: =C14-B14 -> -1 | E14: =COUNTIFS(Simulacion!Q:Q,"B+",Simulacion!T:T,"Mejora") -> 0 | F14: =COUNTIFS(Simulacion!Q:Q,"B+",Simulacion!T:T,"Empeora") -> 6 | G14: =E14-F14 -> -6 | I14: =Simulacion!L6 -> 916.25 | J14: =Simulacion!K6 -> 930 | K14: =J14-I14 -> 13.75 | L14: =Simulacion!V6 -> excelente
A15: B | B15: =COUNTIF(Datos!I:I,"B") -> 14 | C15: =COUNTIF(Simulacion!Q:Q,"B") -> 18 | D15: =C15-B15 -> 4 | E15: =COUNTIFS(Simulacion!Q:Q,"B",Simulacion!T:T,"Mejora") -> 5 | F15: =COUNTIFS(Simulacion!Q:Q,"B",Simulacion!T:T,"Empeora") -> 3 | G15: =E15-F15 -> 2 | I15: =Simulacion!L7 -> 909.79 | J15: =Simulacion!K7 -> 880 | K15: =J15-I15 -> -29.79 | L15: =Simulacion!V7 -> excelente
A16: B- | B16: =COUNTIF(Datos!I:I,"B-") -> 19 | C16: =COUNTIF(Simulacion!Q:Q,"B-") -> 13 | D16: =C16-B16 -> -6 | E16: =COUNTIFS(Simulacion!Q:Q,"B-",Simulacion!T:T,"Mejora") -> 4 | F16: =COUNTIFS(Simulacion!Q:Q,"B-",Simulacion!T:T,"Empeora") -> 3 | G16: =E16-F16 -> 1 | I16: =Simulacion!L8 -> 885.68 | J16: =Simulacion!K8 -> 1000 | K16: =J16-I16 -> 114.32 | L16: =Simulacion!V8 -> excelente
A17: C+ | B17: =COUNTIF(Datos!I:I,"C+") -> 27 | C17: =COUNTIF(Simulacion!Q:Q,"C+") -> 18 | D17: =C17-B17 -> -9 | E17: =COUNTIFS(Simulacion!Q:Q,"C+",Simulacion!T:T,"Mejora") -> 0 | F17: =COUNTIFS(Simulacion!Q:Q,"C+",Simulacion!T:T,"Empeora") -> 12 | G17: =E17-F17 -> -12 | I17: =Simulacion!L9 -> 851.41 | J17: =Simulacion!K9 -> 880 | K17: =J17-I17 -> 28.59 | L17: =Simulacion!V9 -> excelente
A18: C | B18: =COUNTIF(Datos!I:I,"C") -> 28 | C18: =COUNTIF(Simulacion!Q:Q,"C") -> 32 | D18: =C18-B18 -> 4 | E18: =COUNTIFS(Simulacion!Q:Q,"C",Simulacion!T:T,"Mejora") -> 2 | F18: =COUNTIFS(Simulacion!Q:Q,"C",Simulacion!T:T,"Empeora") -> 23 | G18: =E18-F18 -> -21 | I18: =Simulacion!L10 -> 894.95 | J18: =Simulacion!K10 -> 950 | K18: =J18-I18 -> 55.05 | L18: =Simulacion!V10 -> excelente
A19: C- | B19: =COUNTIF(Datos!I:I,"C-") -> 16 | C19: =COUNTIF(Simulacion!Q:Q,"C-") -> 22 | D19: =C19-B19 -> 6 | E19: =COUNTIFS(Simulacion!Q:Q,"C-",Simulacion!T:T,"Mejora") -> 0 | F19: =COUNTIFS(Simulacion!Q:Q,"C-",Simulacion!T:T,"Empeora") -> 15 | G19: =E19-F19 -> -15 | I19: =Simulacion!L11 -> 921.32 | J19: =Simulacion!K11 -> 1000 | K19: =J19-I19 -> 78.68 | L19: =Simulacion!V11 -> excelente
A20: D+ | B20: =COUNTIF(Datos!I:I,"D+") -> 0 | C20: =COUNTIF(Simulacion!Q:Q,"D+") -> 8 | D20: =C20-B20 -> 8 | E20: =COUNTIFS(Simulacion!Q:Q,"D+",Simulacion!T:T,"Mejora") -> 0 | F20: =COUNTIFS(Simulacion!Q:Q,"D+",Simulacion!T:T,"Empeora") -> 5 | G20: =E20-F20 -> -5 | I20: =Simulacion!L12 -> 853.14 | J20: =Simulacion!K12 -> 880 | K20: =J20-I20 -> 26.86 | L20: =Simulacion!V12 -> excelente
A21: D | B21: =COUNTIF(Datos!I:I,"D") -> 29 | C21: =COUNTIF(Simulacion!Q:Q,"D") -> 16 | D21: =C21-B21 -> -13 | E21: =COUNTIFS(Simulacion!Q:Q,"D",Simulacion!T:T,"Mejora") -> 0 | F21: =COUNTIFS(Simulacion!Q:Q,"D",Simulacion!T:T,"Empeora") -> 9 | G21: =E21-F21 -> -9 | I21: =Simulacion!L13 -> 878.98 | J21: =Simulacion!K13 -> 1000 | K21: =J21-I21 -> 121.02 | L21: =Simulacion!V13 -> excelente
A22: F | B22: =COUNTIF(Datos!I:I,"F") -> 12 | C22: =COUNTIF(Simulacion!Q:Q,"F") -> 19 | D22: =C22-B22 -> 7 | E22: =COUNTIFS(Simulacion!Q:Q,"F",Simulacion!T:T,"Mejora") -> 0 | F22: =COUNTIFS(Simulacion!Q:Q,"F",Simulacion!T:T,"Empeora") -> 15 | G22: =E22-F22 -> -15 | I22: =Simulacion!L14 -> 903.93 | J22: =Simulacion!K14 -> 950 | K22: =J22-I22 -> 46.07 | L22: =Simulacion!V14 -> excelente
A23: TOTAL | B23: =SUM(B11:B22) -> 200 | C23: =SUM(C11:C22) -> 200 | D23: =SUM(D11:D22) -> 0 | E23: =SUM(E11:E22) -> 26 | F23: =SUM(F11:F22) -> 92 | G23: =SUM(G11:G22) -> -66 | I23: =Simulacion!L15 -> 850.7 | J23: =Simulacion!K15 -> 950 | K23: =J23-I23 -> 99.3 | L23: =Simulacion!V15 -> excelente
I24: =Simulacion!L16 -> 920.3 | J24: =Simulacion!K16 -> 950 | K24: =J24-I24 -> 29.7 | L24: =Simulacion!V16 -> excelente
A25: IMPACTO POR PERFIL DE RIESGO | I25: =Simulacion!L17 -> 891.1 | J25: =Simulacion!K17 -> 880 | K25: =J25-I25 -> -11.1 | L25: =Simulacion!V17 -> excelente
A26: Perfil | B26: Cantidad | C26: Score Base | D26: Score Sim | E26: Delta | F26: % Impacto | I26: =Simulacion!L18 -> 858.09 | J26: =Simulacion!K18 -> 950 | K26: =J26-I26 -> 91.91 | L26: =Simulacion!V18 -> excelente
A27: EXCELENTE | B27: =COUNTIF(Simulacion!V:V,"excelente") -> 30 | C27: =IFERROR(AVERAGEIF(Simulacion!V:V,"excelente",Datos!H:H),0) -> 935.29467 | D27: =IFERROR(AVERAGEIF(Simulacion!V:V,"excelente",Simulacion!P:P),0) -> 939.58007 | E27: =D27-C27 -> 4.2854 | F27: =IFERROR(E27/C27,0) -> 0.0045818715 | I27: =Simulacion!L19 -> 865.07 | J27: =Simulacion!K19 -> 1000 | K27: =J27-I27 -> 134.93 | L27: =Simulacion!V19 -> excelente
A28: BUENO | B28: =COUNTIF(Simulacion!V:V,"bueno") -> 50 | C28: =IFERROR(AVERAGEIF(Simulacion!V:V,"bueno",Datos!H:H),0) -> 748.3098 | D28: =IFERROR(AVERAGEIF(Simulacion!V:V,"bueno",Simulacion!P:P),0) -> 740.98672 | E28: =D28-C28 -> -7.32308 | F28: =IFERROR(E28/C28,0) -> -0.0097861608 | I28: =Simulacion!L20 -> 859.62 | J28: =Simulacion!K20 -> 930 | K28: =J28-I28 -> 70.38 | L28: =Simulacion!V20 -> excelente
A29: REGULAR | B29: =COUNTIF(Simulacion!V:V,"regular") -> 60 | C29: =IFERROR(AVERAGEIF(Simulacion!V:V,"regular",Datos!H:H),0) -> 577.96933 | D29: =IFERROR(AVERAGEIF(Simulacion!V:V,"regular",Simulacion!P:P),0) -> 562.58103 | E29: =D29-C29 -> -15.3883 | F29: =IFERROR(E29/C29,0) -> -0.026624769 | I29: =Simulacion!L21 -> 919.58 | J29: =Simulacion!K21 -> 950 | K29: =J29-I29 -> 30.42 | L29: =Simulacion!V21 -> excelente
A30: MALO | B30: =COUNTIF(Simulacion!V:V,"malo") -> 40 | C30: =IFERROR(AVERAGEIF(Simulacion!V:V,"malo",Datos!H:H),0) -> 416.94625 | D30: =IFERROR(AVERAGEIF(Simulacion!V:V,"malo",Simulacion!P:P),0) -> 398.532 | E30: =D30-C30 -> -18.41425 | F30: =IFERROR(E30/C30,0) -> -0.044164566 | I30: =Simulacion!L22 -> 938.26 | J30: =Simulacion!K22 -> 1000 | K30: =J30-I30 -> 61.74 | L30: =Simulacion!V22 -> excelente
A31: OUTLIER | B31: =COUNTIF(Simulacion!V:V,"outlier") -> 20 | C31: =IFERROR(AVERAGEIF(Simulacion!V:V,"outlier",Datos!H:H),0) -> 648.763 | D31: =IFERROR(AVERAGEIF(Simulacion!V:V,"outlier",Simulacion!P:P),0) -> 655.25935 | E31: =D31-C31 -> 6.49635 | F31: =IFERROR(E31/C31,0) -> 0.010013441 | I31: =Simulacion!L23 -> 943.56 | J31: =Simulacion!K23 -> 1000 | K31: =J31-I31 -> 56.44 | L31: =Simulacion!V23 -> excelente
I32: =Simulacion!L24 -> 898.56 | J32: =Simulacion!K24 -> 950 | K32: =J32-I32 -> 51.44 | L32: =Simulacion!V24 -> excelente
A33: IMPACTO POR CATEGORIA DE MADUREZ | I33: =Simulacion!L25 -> 915.76 | J33: =Simulacion!K25 -> 930 | K33: =J33-I33 -> 14.24 | L33: =Simulacion!V25 -> excelente
A34: Categoria | B34: Cantidad | C34: Score Base | D34: Score Sim | E34: Delta | F34: Peso PLATAM | I34: =Simulacion!L26 -> 913.11 | J34: =Simulacion!K26 -> 950 | K34: =J34-I34 -> 36.89 | L34: =Simulacion!V26 -> excelente
A35: muy_nuevo | B35: =COUNTIF(Simulacion!U:U,"muy_nuevo") -> 32 | C35: =IFERROR(AVERAGEIF(Simulacion!U:U,"muy_nuevo",Datos!H:H),0) -> 477.35281 | D35: =IFERROR(AVERAGEIF(Simulacion!U:U,"muy_nuevo",Simulacion!P:P),0) -> 452.27484 | E35: =D35-C35 -> -25.077969 | F35: =IFERROR(AVERAGEIF(Simulacion!U:U,"muy_nuevo",Simulacion!O:O),0) -> 0.36875 | I35: =Simulacion!L27 -> 914.55 | J35: =Simulacion!K27 -> 1000 | K35: =J35-I35 -> 85.45 | L35: =Simulacion!V27 -> excelente
A36: nuevo | B36: =COUNTIF(Simulacion!U:U,"nuevo") -> 52 | C36: =IFERROR(AVERAGEIF(Simulacion!U:U,"nuevo",Datos!H:H),0) -> 535.47346 | D36: =IFERROR(AVERAGEIF(Simulacion!U:U,"nuevo",Simulacion!P:P),0) -> 518.96137 | E36: =D36-C36 -> -16.512096 | F36: =IFERROR(AVERAGEIF(Simulacion!U:U,"nuevo",Simulacion!O:O),0) -> 0.46538462 | I36: =Simulacion!L28 -> 946.67 | J36: =Simulacion!K28 -> 1000 | K36: =J36-I36 -> 53.33 | L36: =Simulacion!V28 -> excelente
A37: intermedio | B37: =COUNTIF(Simulacion!U:U,"intermedio") -> 51 | C37: =IFERROR(AVERAGEIF(Simulacion!U:U,"intermedio",Datos!H:H),0) -> 653.72471 | D37: =IFERROR(AVERAGEIF(Simulacion!U:U,"intermedio",Simulacion!P:P),0) -> 646.56814 | E37: =D37-C37 -> -7.1565686 | F37: =IFERROR(AVERAGEIF(Simulacion!U:U,"intermedio",Simulacion!O:O),0) -> 0.56078431 | I37: =Simulacion!L29 -> 943.62 | J37: =Simulacion!K29 -> 880 | K37: =J37-I37 -> -63.62 | L37: =Simulacion!V29 -> excelente
A38: establecido | B38: =COUNTIF(Simulacion!U:U,"establecido") -> 46 | C38: =IFERROR(AVERAGEIF(Simulacion!U:U,"establecido",Datos!H:H),0) -> 772.59022 | D38: =IFERROR(AVERAGEIF(Simulacion!U:U,"establecido",Simulacion!P:P),0) -> 776.28391 | E38: =D38-C38 -> 3.6936957 | F38: =IFERROR(AVERAGEIF(Simulacion!U:U,"establecido",Simulacion!O:O),0) -> 0.67608696 | I38: =Simulacion!L30 -> 924.08 | J38: =Simulacion!K30 -> 930 | K38: =J38-I38 -> 5.92 | L38: =Simulacion!V30 -> excelente
A39: maduro | B39: =COUNTIF(Simulacion!U:U,"maduro") -> 19 | C39: =IFERROR(AVERAGEIF(Simulacion!U:U,"maduro",Datos!H:H),0) -> 937.18842 | D39: =IFERROR(AVERAGEIF(Simulacion!U:U,"maduro",Simulacion!P:P),0) -> 941.85505 | E39: =D39-C39 -> 4.6666316 | F39: =IFERROR(AVERAGEIF(Simulacion!U:U,"maduro",Simulacion!O:O),0) -> 0.76315789 | I39: =Simulacion!L31 -> 901.13 | J39: =Simulacion!K31 -> 950 | K39: =J39-I39 -> 48.87 | L39: =Simulacion!V31 -> excelente
I40: =Simulacion!L32 -> 759.4 | J40: =Simulacion!K32 -> 525 | K40: =J40-I40 -> -234.4 | L40: =Simulacion!V32 -> bueno
A41: DISTRIBUCION DEL CAMBIO | I41: =Simulacion!L33 -> 832.26 | J41: =Simulacion!K33 -> 750 | K41: =J41-I41 -> -82.26 | L41: =Simulacion!V33 -> bueno
A42: Rango | B42: Cantidad | C42: % Total | I42: =Simulacion!L34 -> 804.06 | J42: =Simulacion!K34 -> 725 | K42: =J42-I42 -> -79.06 | L42: =Simulacion!V34 -> bueno
A43: Muy Positivo (>50) | B43: =COUNTIF(Simulacion!S:S,">50") -> 0 | C43: =B43/200 -> 0 | I43: =Simulacion!L35 -> 775.09 | J43: =Simulacion!K35 -> 805 | K43: =J43-I43 -> 29.91 | L43: =Simulacion!V35 -> bueno
A44: Positivo (10 a 50) | B44: =COUNTIFS(Simulacion!S:S,">10",Simulacion!S:S,"<=50") -> 15 | C44: =B44/200 -> 0.075 | I44: =Simulacion!L36 -> 821.46 | J44: =Simulacion!K36 -> 725 | K44: =J44-I44 -> -96.46 | L44: =Simulacion!V36 -> bueno
...

Sheet Analisis Outliers
A1: ANALISIS DE OUTLIERS - DISCREPANCIA HCPN vs PLATAM
A3: Outliers: Clientes donde la diferencia entre HCPN (Experian) y Score PLATAM es mayor a 150 puntos
A5: ID | B5: HCPN | C5: PLATAM Sim | D5: Gap | E5: Tipo Outlier | F5: Categoria | G5: Perfil | H5: Rating Base | I5: Rating Sim | J5: Cambio
A6: =Simulacion!A2 -> 84865655 | B6: =Simulacion!L2 -> 895.92 | C6: =Simulacion!K2 -> 1000 | D6: =ABS(B6-C6) -> 104.08 | E6: =IF(B6>C6,"HCPN > PLATAM","PLATAM > HCPN") -> PLATAM > HCPN | F6: =Simulacion!U2 -> maduro | G6: =Simulacion!V2 -> excelente | H6: =Simulacion!R2 -> A+ | I6: =Simulacion!Q2 -> A+ | J6: =Simulacion!T2 -> Mejora
A7: =Simulacion!A3 -> 39898663 | B7: =Simulacion!L3 -> 911.75 | C7: =Simulacion!K3 -> 1000 | D7: =ABS(B7-C7) -> 88.25 | E7: =IF(B7>C7,"HCPN > PLATAM","PLATAM > HCPN") -> PLATAM > HCPN | F7: =Simulacion!U3 -> establecido | G7: =Simulacion!V3 -> excelente | H7: =Simulacion!R3 -> A+ | I7: =Simulacion!Q3 -> A+ | J7: =Simulacion!T3 -> Mejora
A8: =Simulacion!A4 -> 60106450 | B8: =Simulacion!L4 -> 928.52 | C8: =Simulacion!K4 -> 880 | D8: =ABS(B8-C8) -> 48.52 | E8: =IF(B8>C8,"HCPN > PLATAM","PLATAM > HCPN") -> HCPN > PLATAM | F8: =Simulacion!U4 -> maduro | G8: =Simulacion!V4 -> excelente | H8: =Simulacion!R4 -> A | I8: =Simulacion!Q4 -> A | J8: =Simulacion!T4 -> Igual
A9: =Simulacion!A5 -> 34784923 | B9: =Simulacion!L5 -> 880.46 | C9: =Simulacion!K5 -> 1000 | D9: =ABS(B9-C9) -> 119.54 | E9: =IF(B9>C9,"HCPN > PLATAM","PLATAM > HCPN") -> PLATAM > HCPN | F9: =Simulacion!U5 -> maduro | G9: =Simulacion!V5 -> excelente | H9: =Simulacion!R5 -> A+ | I9: =Simulacion!Q5 -> A+ | J9: =Simulacion!T5 -> Mejora
A10: =Simulacion!A6 -> 41431975 | B10: =Simulacion!L6 -> 916.25 | C10: =Simulacion!K6 -> 930 | D10: =ABS(B10-C10) -> 13.75 | E10: =IF(B10>C10,"HCPN > PLATAM","PLATAM > HCPN") -> PLATAM > HCPN | F10: =Simulacion!U6 -> maduro | G10: =Simulacion!V6 -> excelente | H10: =Simulacion!R6 -> A+ | I10: =Simulacion!Q6 -> A+ | J10: =Simulacion!T6 -> Igual
A11: =Simulacion!A7 -> 70333861 | B11: =Simulacion!L7 -> 909.79 | C11: =Simulacion!K7 -> 880 | D11: =ABS(B11-C11) -> 29.79 | E11: =IF(B11>C11,"HCPN > PLATAM","PLATAM > HCPN") -> HCPN > PLATAM | F11: =Simulacion!U7 -> establecido | G11: =Simulacion!V7 -> excelente | H11: =Simulacion!R7 -> A | I11: =Simulacion!Q7 -> A | J11: =Simulacion!T7 -> Igual
A12: =Simulacion!A8 -> 19016961 | B12: =Simulacion!L8 -> 885.68 | C12: =Simulacion!K8 -> 1000 | D12: =ABS(B12-C12) -> 114.32 | E12: =IF(B12>C12,"HCPN > PLATAM","PLATAM > HCPN") -> PLATAM > HCPN | F12: =Simulacion!U8 -> maduro | G12: =Simulacion!V8 -> excelente | H12: =Simulacion!R8 -> A+ | I12: =Simulacion!Q8 -> A+ | J12: =Simulacion!T8 -> Mejora
A13: =Simulacion!A9 -> 12633705 | B13: =Simulacion!L9 -> 851.41 | C13: =Simulacion!K9 -> 880 | D13: =ABS(B13-C13) -> 28.59 | E13: =IF(B13>C13,"HCPN > PLATAM","PLATAM > HCPN") -> PLATAM > HCPN | F13: =Simulacion!U9 -> maduro | G13: =Simulacion!V9 -> excelente | H13: =Simulacion!R9 -> A | I13: =Simulacion!Q9 -> A | J13: =Simulacion!T9 -> Igual
A14: =Simulacion!A10 -> 99166838 | B14: =Simulacion!L10 -> 894.95 | C14: =Simulacion!K10 -> 950 | D14: =ABS(B14-C14) -> 55.05 | E14: =IF(B14>C14,"HCPN > PLATAM","PLATAM > HCPN") -> PLATAM > HCPN | F14: =Simulacion!U10 -> maduro | G14: =Simulacion!V10 -> excelente | H14: =Simulacion!R10 -> A+ | I14: =Simulacion!Q10 -> A+ | J14: =Simulacion!T10 -> Mejora
A15: =Simulacion!A11 -> 92217102 | B15: =Simulacion!L11 -> 921.32 | C15: =Simulacion!K11 -> 1000 | D15: =ABS(B15-C15) -> 78.68 | E15: =IF(B15>C15,"HCPN > PLATAM","PLATAM > HCPN") -> PLATAM > HCPN | F15: =Simulacion!U11 -> establecido | G15: =Simulacion!V11 -> excelente | H15: =Simulacion!R11 -> A+ | I15: =Simulacion!Q11 -> A+ | J15: =Simulacion!T11 -> Mejora
A16: =Simulacion!A12 -> 11204918 | B16: =Simulacion!L12 -> 853.14 | C16: =Simulacion!K12 -> 880 | D16: =ABS(B16-C16) -> 26.86 | E16: =IF(B16>C16,"HCPN > PLATAM","PLATAM > HCPN") -> PLATAM > HCPN | F16: =Simulacion!U12 -> establecido | G16: =Simulacion!V12 -> excelente | H16: =Simulacion!R12 -> A | I16: =Simulacion!Q12 -> A | J16: =Simulacion!T12 -> Igual
A17: =Simulacion!A13 -> 23938272 | B17: =Simulacion!L13 -> 878.98 | C17: =Simulacion!K13 -> 1000 | D17: =ABS(B17-C17) -> 121.02 | E17: =IF(B17>C17,"HCPN > PLATAM","PLATAM > HCPN") -> PLATAM > HCPN | F17: =Simulacion!U13 -> maduro | G17: =Simulacion!V13 -> excelente | H17: =Simulacion!R13 -> A+ | I17: =Simulacion!Q13 -> A+ | J17: =Simulacion!T13 -> Igual
... A35: =Simulacion!A31 -> 63291059 | B35: =Simulacion!L31 -> 901.13 | C35: =Simulacion!K31 -> 950 | D35: =ABS(B35-C35) -> 48.87 | E35: =IF(B35>C35,"HCPN > PLATAM","PLATAM > HCPN") -> PLATAM > HCPN | F35: =Simulacion!U31 -> maduro | G35: =Simulacion!V31 -> excelente | H35: =Simulacion!R31 -> A+ | I35: =Simulacion!Q31 -> A+ | J35: =Simulacion!T31 -> Igual
A38: RESUMEN DE OUTLIERS:
A39: Total con Gap > 150: | B39: =COUNTIF(Simulacion!S:S,">150")+COUNTIF(Simulacion!S:S,"<-150") -> 0
A40: HCPN > PLATAM (Experian mejor): | B40: =SUMPRODUCT((Simulacion!L2:L201>Simulacion!K2:K201)*(ABS(Simulacion!L2:L201-Simulacion!K2:K201)>150)*1) -> 117
A41: PLATAM > HCPN (Interno mejor): | B41: =SUMPRODUCT((Simulacion!K2:K201>Simulacion!L2:L201)*(ABS(Simulacion!L2:L201-Simulacion!K2:K201)>150)*1) -> 13
